Workbook

Sheet ГОЧ
A1: Дата | B1: Угруповання | C1: Всього бойових зіткнень | D1: Бойові зіткнення | E1: Тривають (бз) | F1: Штурмові дії | G1: Тривають (шд) | H1: Ракетні удари | I1: Застосовано ракет | J1: АУ | K1: КАБ | L1: КАР | M1: ВСЬОГО УДАРІВ БпЛА | N1: Шахеди/Гербера/Пародія | O1: Італмас | P1: Ланцет | Q1: Молнія | R1: Бандероль | S1: Привіт/Куб | T1: FPV-дрони | U1: Обстріли | V1: Всього втрачено позицій | W1: Знищено | X1: Внаслідок ШД | Y1: сам. зал. позиції | Z1: Всього відновлено/виставлено позицій | AA1: Відновлено позицій | AB1: Виставлено позицій | AC1: безповоротні_ЗСУ | AD1: санітарні_ЗСУ | AE1: зниклі безвісті_ЗСУ | AF1: полон_ЗСУ | AG1: Втрати_всього_ЗСУ | AH1: безповоротні_рф | AI1: санітарні_рф | AJ1: полон_рф | AK1: Втрати_всього_рф | AL1: безповоротні_рік_ЗСУ | AM1: санітарні_рік_ЗСУ | AN1: зниклі безвісті_рік_ЗСУ | AO1: полон_рік_ЗСУ | AP1: Втрати_всього_рік_ЗСУ | AQ1: безповоротні_рік_рф | AR1: санітарні_рік_рф | AS1: полон_рік_рф | AT1: Втрати_всього_рік_рф | AU1: безповоротні_всього_рф | AV1: санітарні_всього_рф | AW1: полон_всього_рф | AX1: Втрати_всього_всього_рф | AY1: втрачено_територій | AZ1: відновлено_територій | BA1: втрачені_нп | BB1: відновлені_нп | BC1: втрати_територій_сумарно | BD1: відновлено_територій_сумарно | BE1: втрачені_нп_опис | BF1: відновлені_нп_опис
A2: 46254
A3: =A2 -> 46254 | B3: УСБпС | C3: =SUM(D3,F3) -> 0 | D3: =RANDBETWEEN(0,2) -> 0 | E3: =RANDBETWEEN(0,2) -> 0 | F3: =RANDBETWEEN(0,2) -> 0 | G3: =RANDBETWEEN(0,2) -> 0 | H3: =RANDBETWEEN(0,2) -> 1 | I3: =RANDBETWEEN(0,2) -> 0 | J3: =RANDBETWEEN(0,2) -> 2 | K3: =RANDBETWEEN(0,2) -> 2 | L3: =RANDBETWEEN(0,2) -> 1 | M3: =SUM(N3:T3) -> 36 | N3: =RANDBETWEEN(0,10) -> 7 | O3: =RANDBETWEEN(0,10) -> 5 | P3: =RANDBETWEEN(0,10) -> 6 | Q3: =RANDBETWEEN(0,10) -> 6 | R3: =RANDBETWEEN(0,10) -> 0 | S3: =RANDBETWEEN(0,10) -> 8 | T3: =RANDBETWEEN(0,10) -> 4 | U3: =RANDBETWEEN(10,30) -> 12 | V3: =SUM(W3:Y3) -> 0 | W3: =RANDBETWEEN(0,2) -> 0 | X3: =RANDBETWEEN(0,2) -> 0 | Y3: =RANDBETWEEN(0,2) -> 0 | Z3: =AA3+AB3 -> 2 | AA3: =RANDBETWEEN(0,2) -> 2 | AB3: =RANDBETWEEN(0,2) -> 0 | AC3: =RANDBETWEEN(0,2) -> 0 | AD3: =RANDBETWEEN(0,2) -> 2 | AE3: =RANDBETWEEN(0,2) -> 2 | AF3: =RANDBETWEEN(0,2) -> 1 | AG3: =SUM(AC3:AF3) -> 5 | AH3: =RANDBETWEEN(1,10) -> 2 | AI3: =RANDBETWEEN(1,10) -> 5 | AJ3: =RANDBETWEEN(1,10) -> 8 | AK3: =SUM(AH3:AJ3) -> 15 | AY3: =RANDBETWEEN(1,10)/100 -> 0.01 | AZ3: =RANDBETWEEN(1,10)/100 -> 0.02 | BA3: 0 | BB3: 0 | BC3: 1200 | BD3: 1200
A4: =A3 -> 46254 | B4: УВ (с) "Захід" | C4: =SUM(D4,F4) -> 4 | D4: =RANDBETWEEN(0,2) -> 2 | E4: =RANDBETWEEN(0,2) -> 2 | F4: =RANDBETWEEN(0,2) -> 2 | G4: =RANDBETWEEN(0,2) -> 1 | H4: =RANDBETWEEN(0,2) -> 0 | I4: =RANDBETWEEN(0,2) -> 1 | J4: =RANDBETWEEN(0,2) -> 0 | K4: =RANDBETWEEN(0,2) -> 1 | L4: =RANDBETWEEN(0,2) -> 2 | M4: =SUM(N4:T4) -> 33 | N4: =RANDBETWEEN(0,10) -> 8 | O4: =RANDBETWEEN(0,10) -> 9 | P4: =RANDBETWEEN(0,10) -> 8 | Q4: =RANDBETWEEN(0,10) -> 4 | R4: =RANDBETWEEN(0,10) -> 1 | S4: =RANDBETWEEN(0,10) -> 3 | T4: =RANDBETWEEN(0,10) -> 0 | U4: =RANDBETWEEN(10,30) -> 21 | V4: =SUM(W4:Y4) -> 1 | W4: =RANDBETWEEN(0,2) -> 0 | X4: =RANDBETWEEN(0,2) -> 1 | Y4: =RANDBETWEEN(0,2) -> 0 | Z4: =AA4+AB4 -> 2 | AA4: =RANDBETWEEN(0,2) -> 2 | AB4: =RANDBETWEEN(0,2) -> 0 | AC4: =RANDBETWEEN(0,2) -> 0 | AD4: =RANDBETWEEN(0,2) -> 2 | AE4: =RANDBETWEEN(0,2) -> 0 | AF4: =RANDBETWEEN(0,2) -> 2 | AG4: =SUM(AC4:AF4) -> 4 | AH4: =RANDBETWEEN(1,10) -> 2 | AI4: =RANDBETWEEN(1,10) -> 4 | AJ4: =RANDBETWEEN(1,10) -> 6 | AK4: =SUM(AH4:AJ4) -> 12 | AY4: =RANDBETWEEN(1,10)/100 -> 0.09 | AZ4: =RANDBETWEEN(1,10)/100 -> 0.01 | BA4: 0 | BB4: 0 | BC4: 1200 | BD4: 1200
A5: =A4 -> 46254 | B5: 12 АК | C5: =SUM(D5,F5) -> 0 | D5: 0 | E5: 0 | F5: 0 | G5: 0 | H5: 0 | I5: 0 | J5: 0 | K5: 0 | L5: 0 | M5: =SUM(N5:T5) -> 0 | N5: 0 | O5: 0 | P5: 0 | Q5: 0 | R5: 0 | S5: 0 | T5: 0 | U5: 0 | V5: =SUM(W5:Y5) -> 0 | W5: 0 | X5: 0 | Y5: 0 | Z5: =AA5+AB5 -> 0 | AA5: 0 | AB5: 0 | AC5: 0 | AD5: 0 | AE5: 0 | AF5: 0 | AG5: =SUM(AC5:AF5) -> 0 | AH5: 0 | AI5: 0 | AJ5: 0 | AK5: =SUM(AH5:AJ5) -> 0 | AY5: =SUM(AY3:AY4) -> 0.1 | AZ5: =SUM(AZ3:AZ4) -> 0.03 | BA5: =SUM(BA3:BA4) -> 0 | BB5: =SUM(BB3:BB4) -> 0 | BC5: =SUM(BC3:BC4) -> 2400 | BD5: =SUM(BD3:BD4) -> 2400
A6: =A5 -> 46254 | B6: 15 АК | C6: =SUM(D6,F6) -> 3 | D6: =RANDBETWEEN(0,2) -> 2 | E6: =RANDBETWEEN(0,2) -> 1 | F6: =RANDBETWEEN(0,2) -> 1 | G6: =RANDBETWEEN(0,2) -> 0 | H6: =RANDBETWEEN(0,2) -> 0 | I6: =RANDBETWEEN(0,2) -> 0 | J6: =RANDBETWEEN(0,2) -> 0 | K6: =RANDBETWEEN(0,2) -> 1 | L6: =RANDBETWEEN(0,2) -> 2 | M6: =SUM(N6:T6) -> 42 | N6: =RANDBETWEEN(0,10) -> 5 | O6: =RANDBETWEEN(0,10) -> 1 | P6: =RANDBETWEEN(0,10) -> 9 | Q6: =RANDBETWEEN(0,10) -> 10 | R6: =RANDBETWEEN(0,10) -> 0 | S6: =RANDBETWEEN(0,10) -> 8 | T6: =RANDBETWEEN(0,10) -> 9 | U6: =RANDBETWEEN(10,30) -> 27 | V6: =SUM(W6:Y6) -> 3 | W6: =RANDBETWEEN(0,2) -> 0 | X6: =RANDBETWEEN(0,2) -> 1 | Y6: =RANDBETWEEN(0,2) -> 2 | Z6: =SUM(AA6:AB6) -> 3 | AA6: =RANDBETWEEN(0,2) -> 1 | AB6: =RANDBETWEEN(0,2) -> 2 | AC6: =RANDBETWEEN(0,2) -> 1 | AD6: =RANDBETWEEN(0,2) -> 2 | AE6: =RANDBETWEEN(0,2) -> 0 | AF6: =RANDBETWEEN(0,2) -> 0 | AG6: =SUM(AC6:AF6) -> 3 | AH6: =RANDBETWEEN(1,10) -> 8 | AI6: =RANDBETWEEN(1,10) -> 6 | AJ6: =RANDBETWEEN(1,10) -> 9 | AK6: =SUM(AH6:AJ6) -> 23 | AY6: =RANDBETWEEN(1,10)/10 -> 0.1 | AZ6: =RANDBETWEEN(1,10)/10 -> 0.6 | BA6: 0 | BB6: 0 | BC6: 1200 | BD6: 1200
A7: =A6 -> 46254 | B7: 18 АК | C7: =SUM(D7,F7) -> 1 | D7: =RANDBETWEEN(0,2) -> 1 | E7: =RANDBETWEEN(0,2) -> 1 | F7: =RANDBETWEEN(0,2) -> 0 | G7: =RANDBETWEEN(0,2) -> 2 | H7: =RANDBETWEEN(0,2) -> 1 | I7: =RANDBETWEEN(0,2) -> 2 | J7: =RANDBETWEEN(0,2) -> 2 | K7: =RANDBETWEEN(0,2) -> 2 | L7: =RANDBETWEEN(0,2) -> 2 | M7: =SUM(N7:T7) -> 37 | N7: =RANDBETWEEN(0,10) -> 8 | O7: =RANDBETWEEN(0,10) -> 0 | P7: =RANDBETWEEN(0,10) -> 5 | Q7: =RANDBETWEEN(0,10) -> 8 | R7: =RANDBETWEEN(0,10) -> 6 | S7: =RANDBETWEEN(0,10) -> 0 | T7: =RANDBETWEEN(0,10) -> 10 | U7: =RANDBETWEEN(10,30) -> 29 | V7: =SUM(W7:Y7) -> 6 | W7: =RANDBETWEEN(0,2) -> 2 | X7: =RANDBETWEEN(0,2) -> 2 | Y7: =RANDBETWEEN(0,2) -> 2 | Z7: =SUM(AA7:AB7) -> 1 | AA7: =RANDBETWEEN(0,2) -> 0 | AB7: =RANDBETWEEN(0,2) -> 1 | AC7: =RANDBETWEEN(0,2) -> 2 | AD7: =RANDBETWEEN(0,2) -> 0 | AE7: =RANDBETWEEN(0,2) -> 0 | AF7: =RANDBETWEEN(0,2) -> 1 | AG7: =SUM(AC7:AF7) -> 3 | AH7: =RANDBETWEEN(1,10) -> 7 | AI7: =RANDBETWEEN(1,10) -> 7 | AJ7: =RANDBETWEEN(1,10) -> 5 | AK7: =SUM(AH7:AJ7) -> 19 | AY7: =RANDBETWEEN(1,10)/10 -> 0.7 | AZ7: =RANDBETWEEN(1,10)/10 -> 0.5 | BA7: 0 | BB7: 0 | BC7: 1200 | BD7: 1200
A8: =A7 -> 46254 | B8: УВ (с) "Північ" | C8: =SUM(D8,F8) -> 4 | D8: =SUM(D6:D7) -> 3 | E8: =SUM(E6:E7) -> 2 | F8: =SUM(F6:F7) -> 1 | G8: =SUM(G6:G7) -> 2 | H8: =SUM(H6:H7) -> 1 | I8: =SUM(I6:I7) -> 2 | J8: =SUM(J6:J7) -> 2 | K8: =SUM(K6:K7) -> 3 | L8: =SUM(L6:L7) -> 4 | M8: =SUM(N8:T8) -> 73 | N8: =SUM(N6:N7) -> 13 | O8: =SUM(O6:O7) -> 1 | P8: =SUM(P6:P7) -> 14 | Q8: =SUM(Q6:Q7) -> 18 | R8: 0 | S8: =SUM(S6:S7) -> 8 | T8: =SUM(T6:T7) -> 19 | U8: =SUM(U6:U7) -> 56 | V8: =SUM(W8:Y8) -> 9 | W8: =SUM(W6:W7) -> 2 | X8: =SUM(X6:X7) -> 3 | Y8: =SUM(Y6:Y7) -> 4 | Z8: =SUM(AA8:AB8) -> 4 | AA8: =SUM(AA6:AA7) -> 1 | AB8: =SUM(AB6:AB7) -> 3 | AC8: =SUM(AC6:AC7) -> 3 | AD8: =SUM(AD6:AD7) -> 2 | AE8: =SUM(AE6:AE7) -> 0 | AF8: =SUM(AF6:AF7) -> 1 | AG8: =SUM(AC8:AF8) -> 6 | AH8: =SUM(AH6:AH7) -> 15 | AI8: =SUM(AI6:AI7) -> 13 | AJ8: =SUM(AJ6:AJ7) -> 14 | AK8: =SUM(AH8:AJ8) -> 42 | AY8: =SUM(AY6:AY7) -> 0.8 | AZ8: =SUM(AZ6:AZ7) -> 1.1 | BA8: =SUM(BA6:BA7) -> 0 | BB8: =SUM(BB6:BB7) -> 0 | BC8: =SUM(BC6:BC7) -> 2400 | BD8: =SUM(BD6:BD7) -> 2400 | BE8: =TEXTJOIN(", ",TRUE,BE6:BE7) | BF8: =TEXTJOIN(", ",TRUE,BF6:BF7)
A9: =A8 -> 46254 | B9: УВ "Курськ" | C9: =SUM(D9,F9) -> 5 | D9: 3 | E9: 0 | F9: 2 | G9: 2 | H9: 0 | I9: 0 | J9: 1 | K9: 1 | L9: 0 | M9: =SUM(N9:T9) -> 38 | N9: 0 | O9: 0 | P9: 0 | Q9: 9 | R9: 0 | S9: 0 | T9: 29 | U9: 7 | V9: =W9+X9+Y9 -> 0 | W9: 0 | X9: 0 | Y9: 0 | Z9: =SUM(AA9:AB9) -> 0 | AA9: 0 | AB9: 0 | AC9: 0 | AD9: 1 | AE9: 0 | AF9: 0 | AG9: =SUM(AC9:AF9) -> 1 | AH9: 6 | AI9: 5 | AJ9: 0 | AK9: =SUM(AH9:AJ9) -> 11 | AY9: =RANDBETWEEN(1,10) -> 8 | AZ9: =RANDBETWEEN(1,10) -> 9 | BA9: 2 | BB9: 0 | BC9: 0 | BD9: 0 | BE9: Курськ, Рильск
A10: =A9 -> 46254 | B10: 14 АК | C10: =SUM(D10,F10) -> 2 | D10: =RANDBETWEEN(0,2) -> 2 | E10: =RANDBETWEEN(0,2) -> 2 | F10: =RANDBETWEEN(0,2) -> 0 | G10: =RANDBETWEEN(0,2) -> 0 | H10: =RANDBETWEEN(0,2) -> 1 | I10: =RANDBETWEEN(0,2) -> 2 | J10: =RANDBETWEEN(0,2) -> 2 | K10: =RANDBETWEEN(0,2) -> 1 | L10: =RANDBETWEEN(0,2) -> 0 | M10: =SUM(N10:T10) -> 17 | N10: =RANDBETWEEN(0,10) -> 2 | O10: =RANDBETWEEN(0,10) -> 2 | P10: =RANDBETWEEN(0,10) -> 0 | Q10: =RANDBETWEEN(0,10) -> 4 | R10: =RANDBETWEEN(0,10) -> 1 | S10: =RANDBETWEEN(0,10) -> 4 | T10: =RANDBETWEEN(0,10) -> 4 | U10: =RANDBETWEEN(10,30) -> 11 | V10: =W10+X10+Y10 -> 3 | W10: =RANDBETWEEN(0,2) -> 2 | X10: =RANDBETWEEN(0,2) -> 0 | Y10: =RANDBETWEEN(0,2) -> 1 | Z10: =AA10+AB10 -> 4 | AA10: =RANDBETWEEN(0,2) -> 2 | AB10: =RANDBETWEEN(0,2) -> 2 | AC10: =RANDBETWEEN(0,2) -> 1 | AD10: =RANDBETWEEN(0,2) -> 2 | AE10: =RANDBETWEEN(0,2) -> 0 | AF10: =RANDBETWEEN(0,2) -> 0 | AG10: =SUM(AC10:AF10) -> 3 | AH10: =RANDBETWEEN(1,10) -> 1 | AI10: =RANDBETWEEN(1,10) -> 3 | AJ10: =RANDBETWEEN(1,10) -> 2 | AK10: =SUM(AH10:AJ10) -> 6 | AY10: =RANDBETWEEN(1,10)/10 -> 0.5 | AZ10: =RANDBETWEEN(1,10)/10 -> 0.3 | BA10: 1 | BB10: 0 | BC10: 1200 | BD10: 1200 | BE10: Олександівка
A11: =A10 -> 46254 | B11: 2 КНГУ "Хартія" | C11: =SUM(D11,F11) -> 2 | D11: =RANDBETWEEN(0,2) -> 2 | E11: =RANDBETWEEN(0,2) -> 0 | F11: =RANDBETWEEN(0,2) -> 0 | G11: =RANDBETWEEN(0,2) -> 0 | H11: =RANDBETWEEN(0,2) -> 1 | I11: =RANDBETWEEN(0,2) -> 1 | J11: =RANDBETWEEN(0,2) -> 1 | K11: =RANDBETWEEN(0,2) -> 2 | L11: =RANDBETWEEN(0,2) -> 1 | M11: =SUM(N11:T11) -> 43 | N11: =RANDBETWEEN(0,10) -> 2 | O11: =RANDBETWEEN(0,10) -> 9 | P11: =RANDBETWEEN(0,10) -> 6 | Q11: =RANDBETWEEN(0,10) -> 7 | R11: =RANDBETWEEN(0,10) -> 8 | S11: =RANDBETWEEN(0,10) -> 10 | T11: =RANDBETWEEN(0,10) -> 1 | U11: =RANDBETWEEN(10,30) -> 12 | V11: =W11+X11+Y11 -> 5 | W11: =RANDBETWEEN(0,2) -> 1 | X11: =RANDBETWEEN(0,2) -> 2 | Y11: =RANDBETWEEN(0,2) -> 2 | Z11: =AA11+AB11 -> 4 | AA11: =RANDBETWEEN(0,2) -> 2 | AB11: =RANDBETWEEN(0,2) -> 2 | AC11: =RANDBETWEEN(0,2) -> 1 | AD11: =RANDBETWEEN(0,2) -> 1 | AE11: =RANDBETWEEN(0,2) -> 0 | AF11: =RANDBETWEEN(0,2) -> 0 | AG11: =SUM(AC11:AF11) -> 2 | AH11: =RANDBETWEEN(1,10) -> 2 | AI11: =RANDBETWEEN(1,10) -> 3 | AJ11: =RANDBETWEEN(1,10) -> 2 | AK11: =SUM(AH11:AJ11) -> 7 | AY11: =RANDBETWEEN(1,10)/10 -> 1 | AZ11: =RANDBETWEEN(1,10)/10 -> 1 | BA11: 1 | BB11: 2 | BC11: 1200 | BD11: 1200 | BE11: Пантелеймонівка | BF11: Загреблі, Верхні води
A12: =A11 -> 46254 | B12: 16 АК | C12: =SUM(D12,F12) -> 3 | D12: =RANDBETWEEN(0,2) -> 2 | E12: =RANDBETWEEN(0,2) -> 0 | F12: =RANDBETWEEN(0,2) -> 1 | G12: =RANDBETWEEN(0,2) -> 0 | H12: =RANDBETWEEN(0,2) -> 0 | I12: =RANDBETWEEN(0,2) -> 1 | J12: =RANDBETWEEN(0,2) -> 2 | K12: =RANDBETWEEN(0,2) -> 0 | L12: =RANDBETWEEN(0,2) -> 1 | M12: =SUM(N12:T12) -> 45 | N12: =RANDBETWEEN(0,10) -> 10 | O12: =RANDBETWEEN(0,10) -> 7 | P12: =RANDBETWEEN(0,10) -> 4 | Q12: =RANDBETWEEN(0,10) -> 5 | R12: =RANDBETWEEN(0,10) -> 8 | S12: =RANDBETWEEN(0,10) -> 5 | T12: =RANDBETWEEN(0,10) -> 6 | U12: =RANDBETWEEN(10,30) -> 12 | V12: =W12+X12+Y12 -> 1 | W12: =RANDBETWEEN(0,2) -> 0 | X12: =RANDBETWEEN(0,2) -> 1 | Y12: =RANDBETWEEN(0,2) -> 0 | Z12: =AA12+AB12 -> 1 | AA12: =RANDBETWEEN(0,2) -> 0 | AB12: =RANDBETWEEN(0,2) -> 1 | AC12: =RANDBETWEEN(0,2) -> 0 | AD12: =RANDBETWEEN(0,2) -> 0 | AE12: =RANDBETWEEN(0,2) -> 2 | AF12: =RANDBETWEEN(0,2) -> 1 | AG12: =SUM(AC12:AF12) -> 3 | AH12: =RANDBETWEEN(1,10) -> 6 | AI12: =RANDBETWEEN(1,10) -> 6 | AJ12: =RANDBETWEEN(1,10) -> 5 | AK12: =SUM(AH12:AJ12) -> 17 | AY12: =RANDBETWEEN(1,10)/10 -> 0.8 | AZ12: =RANDBETWEEN(1,10)/10 -> 0.9 | BA12: 0 | BB12: 0 | BC12: 1200 | BD12: 1200
A13: =A12 -> 46254 | B13: 10 АК | C13: =SUM(D13,F13) -> 1 | D13: =RANDBETWEEN(0,2) -> 1 | E13: =RANDBETWEEN(0,2) -> 0 | F13: =RANDBETWEEN(0,2) -> 0 | G13: =RANDBETWEEN(0,2) -> 1 | H13: =RANDBETWEEN(0,2) -> 2 | I13: =RANDBETWEEN(0,2) -> 2 | J13: =RANDBETWEEN(0,2) -> 0 | K13: =RANDBETWEEN(0,2) -> 1 | L13: =RANDBETWEEN(0,2) -> 1 | M13: =SUM(N13:T13) -> 48 | N13: =RANDBETWEEN(0,10) -> 10 | O13: =RANDBETWEEN(0,10) -> 2 | P13: =RANDBETWEEN(0,10) -> 8 | Q13: =RANDBETWEEN(0,10) -> 9 | R13: =RANDBETWEEN(0,10) -> 3 | S13: =RANDBETWEEN(0,10) -> 7 | T13: =RANDBETWEEN(0,10) -> 9 | U13: =RANDBETWEEN(10,30) -> 27 | V13: =W13+X13+Y13 -> 3 | W13: =RANDBETWEEN(0,2) -> 2 | X13: =RANDBETWEEN(0,2) -> 0 | Y13: =RANDBETWEEN(0,2) -> 1 | Z13: =AA13+AB13 -> 2 | AA13: =RANDBETWEEN(0,2) -> 1 | AB13: =RANDBETWEEN(0,2) -> 1 | AC13: =RANDBETWEEN(0,2) -> 0 | AD13: =RANDBETWEEN(0,2) -> 1 | AE13: =RANDBETWEEN(0,2) -> 2 | AF13: =RANDBETWEEN(0,2) -> 1 | AG13: =SUM(AC13:AF13) -> 4 | AH13: =RANDBETWEEN(1,10) -> 10 | AI13: =RANDBETWEEN(1,10) -> 1 | AJ13: =RANDBETWEEN(1,10) -> 9 | AK13: =SUM(AH13:AJ13) -> 20 | AY13: =RANDBETWEEN(1,10)/10 -> 0.4 | AZ13: =RANDBETWEEN(1,10)/10 -> 0.9 | BA13: 1 | BB13: 0 | BC13: 1200 | BD13: 1200 | BE13: Миколаївка
A14: =A13 -> 46254 | B14: 3 АК | C14: =SUM(D14,F14) -> 2 | D14: =RANDBETWEEN(0,2) -> 2 | E14: =RANDBETWEEN(0,2) -> 1 | F14: =RANDBETWEEN(0,2) -> 0 | G14: =RANDBETWEEN(0,2) -> 1 | H14: =RANDBETWEEN(0,2) -> 2 | I14: =RANDBETWEEN(0,2) -> 2 | J14: =RANDBETWEEN(0,2) -> 1 | K14: =RANDBETWEEN(0,2) -> 0 | L14: =RANDBETWEEN(0,2) -> 0 | M14: =SUM(N14:T14) -> 32 | N14: =RANDBETWEEN(0,10) -> 6 | O14: =RANDBETWEEN(0,10) -> 10 | P14: =RANDBETWEEN(0,10) -> 0 | Q14: =RANDBETWEEN(0,10) -> 5 | R14: =RANDBETWEEN(0,10) -> 1 | S14: =RANDBETWEEN(0,10) -> 8 | T14: =RANDBETWEEN(0,10) -> 2 | U14: =RANDBETWEEN(10,30) -> 14 | V14: =W14+X14+Y14 -> 2 | W14: =RANDBETWEEN(0,2) -> 1 | X14: =RANDBETWEEN(0,2) -> 1 | Y14: =RANDBETWEEN(0,2) -> 0 | Z14: =AA14+AB14 -> 0 | AA14: =RANDBETWEEN(0,2) -> 0 | AB14: =RANDBETWEEN(0,2) -> 0 | AC14: =RANDBETWEEN(0,2) -> 0 | AD14: =RANDBETWEEN(0,2) -> 0 | AE14: =RANDBETWEEN(0,2) -> 0 | AF14: =RANDBETWEEN(0,2) -> 2 | AG14: =SUM(AC14:AF14) -> 2 | AH14: =RANDBETWEEN(1,10) -> 10 | AI14: =RANDBETWEEN(1,10) -> 9 | AJ14: =RANDBETWEEN(1,10) -> 8 | AK14: =SUM(AH14:AJ14) -> 27 | AY14: =RANDBETWEEN(1,10)/10 -> 0.5 | AZ14: =RANDBETWEEN(1,10)/10 -> 0.4 | BA14: 0 | BB14: 1 | BC14: 1200 | BD14: 1200 | BF14: Ступочки
A15: =A14 -> 46254 | B15: УОС | C15: =SUM(D15,F15) -> 10 | D15: =D10+D11+D12+D13+D14 -> 9 | E15: =E10+E11+E12+E13+E14 -> 3 | F15: =F10+F11+F12+F13+F14 -> 1 | G15: =G10+G11+G12+G13+G14 -> 2 | H15: =H10+H11+H12+H13+H14 -> 6 | I15: =I10+I11+I12+I13+I14 -> 8 | J15: =J10+J11+J12+J13+J14 -> 6 | K15: =K10+K11+K12+K13+K14 -> 4 | L15: =L10+L11+L12+L13+L14 -> 3 | M15: =SUM(N15:T15) -> 185 | N15: =N10+N11+N12+N13+N14 -> 30 | O15: =O10+O11+O12+O13+O14 -> 30 | P15: =P10+P11+P12+P13+P14 -> 18 | Q15: =Q10+Q11+Q12+Q13+Q14 -> 30 | R15: =R10+R11+R12+R13+R14 -> 21 | S15: =S10+S11+S12+S13+S14 -> 34 | T15: =T10+T11+T12+T13+T14 -> 22 | U15: =U10+U11+U12+U13+U14 -> 76 | V15: =W15+X15+Y15 -> 14 | W15: =W10+W11+W12+W13+W14 -> 6 | X15: =X10+X11+X12+X13+X14 -> 4 | Y15: =Y10+Y11+Y12+Y13+Y14 -> 4 | Z15: =AA15+AB15 -> 11 | AA15: =AA10+AA11+AA12+AA13+AA14 -> 5 | AB15: =AB10+AB11+AB12+AB13+AB14 -> 6 | AC15: =AC10+AC11+AC12+AC13+AC14 -> 2 | AD15: =AE10+AD11+AD12+AD13+AD14 -> 2 | AE15: =AE10+AE11+AE12+AE13+AE14 -> 4 | AF15: =AF10+AF11+AF12+AF13+AF14 -> 4 | AG15: =SUM(AC15:AF15) -> 12 | AH15: =AH10+AH11+AH12+AH13+AH14 -> 29 | AI15: =AI10+AI11+AI12+AI13+AI14 -> 22 | AJ15: =AJ10+AJ11+AJ12+AJ13+AJ14 -> 26 | AK15: =SUM(AH15:AJ15) -> 77 | AY15: =AY10+AY11+AY12+AY13+AY14 -> 3.2 | AZ15: =AZ10+AZ11+AZ12+AZ13+AZ14 -> 3.5 | BA15: =BA10+BA11+BA12+BA13+BA14 -> 3 | BB15: =BB10+BB11+BB12+BB13+BB14 -> 3 | BC15: =BC10+BC11+BC12+BC13+BC14 -> 6000 | BD15: =BD10+BD11+BD12+BD13+BD14 -> 6000 | BE15: =TEXTJOIN(", ",TRUE,BE10:BE14) -> Олександівка, Пантелеймонівка, Миколаївка | BF15: =TEXTJOIN(", ",TRUE,BF10:BF14) -> Загреблі, Верхні води, Ступочки
A16: =A15 -> 46254 | B16: 11 АК | C16: =SUM(D16,F16) -> 4 | D16: =RANDBETWEEN(0,2) -> 2 | E16: =RANDBETWEEN(0,2) -> 2 | F16: =RANDBETWEEN(0,2) -> 2 | G16: =RANDBETWEEN(0,2) -> 2 | H16: =RANDBETWEEN(0,2) -> 0 | I16: =RANDBETWEEN(0,2) -> 0 | J16: =RANDBETWEEN(0,2) -> 1 | K16: =RANDBETWEEN(0,2) -> 2 | L16: =RANDBETWEEN(0,2) -> 1 | M16: =SUM(N16:T16) -> 40 | N16: =RANDBETWEEN(0,10) -> 4 | O16: =RANDBETWEEN(0,10) -> 9 | P16: =RANDBETWEEN(0,10) -> 6 | Q16: =RANDBETWEEN(0,10) -> 2 | R16: =RANDBETWEEN(0,10) -> 6 | S16: =RANDBETWEEN(0,10) -> 10 | T16: =RANDBETWEEN(0,10) -> 3 | U16: =RANDBETWEEN(10,30) -> 26 | V16: =W16+X16+Y16 -> 3 | W16: =RANDBETWEEN(0,2) -> 2 | X16: =RANDBETWEEN(0,2) -> 0 | Y16: =RANDBETWEEN(0,2) -> 1 | Z16: =AA16+AB16 -> 0 | AA16: =RANDBETWEEN(0,2) -> 0 | AB16: =RANDBETWEEN(0,2) -> 0 | AC16: =RANDBETWEEN(0,2) -> 1 | AD16: =RANDBETWEEN(0,2) -> 2 | AE16: =RANDBETWEEN(0,2) -> 2 | AF16: =RANDBETWEEN(0,2) -> 1 | AG16: =SUM(AC16:AF16) -> 6 | AH16: =RANDBETWEEN(1,10) -> 6 | AI16: =RANDBETWEEN(1,10) -> 3 | AJ16: =RANDBETWEEN(1,10) -> 1 | AK16: =SUM(AH16:AJ16) -> 10 | AY16: =RANDBETWEEN(1,10)/10 -> 0.6 | AZ16: =RANDBETWEEN(1,10)/10 -> 0.7 | BA16: 0 | BB16: 0 | BC16: 1200 | BD16: 1200
A17: =A16 -> 46254 | B17: 19 АК | C17: =SUM(D17,F17) -> 3 | D17: =RANDBETWEEN(0,2) -> 1 | E17: =RANDBETWEEN(0,2) -> 0 | F17: =RANDBETWEEN(0,2) -> 2 | G17: =RANDBETWEEN(0,2) -> 2 | H17: =RANDBETWEEN(0,2) -> 1 | I17: =RANDBETWEEN(0,2) -> 1 | J17: =RANDBETWEEN(0,2) -> 1 | K17: =RANDBETWEEN(0,2) -> 0 | L17: =RANDBETWEEN(0,2) -> 1 | M17: =SUM(N17:T17) -> 45 | N17: =RANDBETWEEN(0,10) -> 9 | O17: =RANDBETWEEN(0,10) -> 2 | P17: =RANDBETWEEN(0,10) -> 5 | Q17: =RANDBETWEEN(0,10) -> 8 | R17: =RANDBETWEEN(0,10) -> 4 | S17: =RANDBETWEEN(0,10) -> 9 | T17: =RANDBETWEEN(0,10) -> 8 | U17: =RANDBETWEEN(10,30) -> 26 | V17: =W17+X17+Y17 -> 2 | W17: =RANDBETWEEN(0,2) -> 1 | X17: =RANDBETWEEN(0,2) -> 1 | Y17: =RANDBETWEEN(0,2) -> 0 | Z17: =AA17+AB17 -> 1 | AA17: =RANDBETWEEN(0,2) -> 0 | AB17: =RANDBETWEEN(0,2) -> 1 | AC17: =RANDBETWEEN(0,2) -> 0 | AD17: =RANDBETWEEN(0,2) -> 0 | AE17: =RANDBETWEEN(0,2) -> 0 | AF17: =RANDBETWEEN(0,2) -> 0 | AG17: =SUM(AC17:AF17) -> 0 | AH17: =RANDBETWEEN(1,10) -> 5 | AI17: =RANDBETWEEN(1,10) -> 4 | AJ17: =RANDBETWEEN(1,10) -> 10 | AK17: =SUM(AH17:AJ17) -> 19 | AY17: =RANDBETWEEN(1,10)/10 -> 0.2 | AZ17: =RANDBETWEEN(1,10)/10 -> 0.3 | BA17: 0 | BB17: 0 | BC17: 1200 | BD17: 1200
A18: =A17 -> 46254 | B18: 1 КНГУ "Азов" | C18: =SUM(D18,F18) -> 4 | D18: =RANDBETWEEN(0,2) -> 2 | E18: =RANDBETWEEN(0,2) -> 0 | F18: =RANDBETWEEN(0,2) -> 2 | G18: =RANDBETWEEN(0,2) -> 2 | H18: =RANDBETWEEN(0,2) -> 0 | I18: =RANDBETWEEN(0,2) -> 1 | J18: =RANDBETWEEN(0,2) -> 0 | K18: =RANDBETWEEN(0,2) -> 2 | L18: =RANDBETWEEN(0,2) -> 1 | M18: =SUM(N18:T18) -> 46 | N18: =RANDBETWEEN(0,10) -> 5 | O18: =RANDBETWEEN(0,10) -> 8 | P18: =RANDBETWEEN(0,10) -> 7 | Q18: =RANDBETWEEN(0,10) -> 8 | R18: =RANDBETWEEN(0,10) -> 5 | S18: =RANDBETWEEN(0,10) -> 10 | T18: =RANDBETWEEN(0,10) -> 3 | U18: =RANDBETWEEN(10,30) -> 21 | V18: =W18+X18+Y18 -> 4 | W18: =RANDBETWEEN(0,2) -> 2 | X18: =RANDBETWEEN(0,2) -> 0 | Y18: =RANDBETWEEN(0,2) -> 2 | Z18: =AA18+AB18 -> 0 | AA18: =RANDBETWEEN(0,2) -> 0 | AB18: =RANDBETWEEN(0,2) -> 0 | AC18: =RANDBETWEEN(0,2) -> 0 | AD18: =RANDBETWEEN(0,2) -> 0 | AE18: =RANDBETWEEN(0,2) -> 2 | AF18: =RANDBETWEEN(0,2) -> 0 | AG18: =SUM(AC18:AF18) -> 2 | AH18: =RANDBETWEEN(1,10) -> 10 | AI18: =RANDBETWEEN(1,10) -> 4 | AJ18: =RANDBETWEEN(1,10) -> 10 | AK18: =SUM(AH18:AJ18) -> 24 | AY18: =RANDBETWEEN(1,10)/10 -> 0.3 | AZ18: =RANDBETWEEN(1,10)/10 -> 0.8 | BA18: 0 | BB18: 0 | BC18: 1200 | BD18: 1200
A19: =A18 -> 46254 | B19: 7 КШР | C19: =SUM(D19,F19) -> 2 | D19: =RANDBETWEEN(0,2) -> 0 | E19: =RANDBETWEEN(0,2) -> 0 | F19: =RANDBETWEEN(0,2) -> 2 | G19: =RANDBETWEEN(0,2) -> 0 | H19: =RANDBETWEEN(0,2) -> 1 | I19: =RANDBETWEEN(0,2) -> 1 | J19: =RANDBETWEEN(0,2) -> 2 | K19: =RANDBETWEEN(0,2) -> 1 | L19: =RANDBETWEEN(0,2) -> 0 | M19: =SUM(N19:T19) -> 27 | N19: =RANDBETWEEN(0,10) -> 10 | O19: =RANDBETWEEN(0,10) -> 3 | P19: =RANDBETWEEN(0,10) -> 5 | Q19: =RANDBETWEEN(0,10) -> 2 | R19: =RANDBETWEEN(0,10) -> 5 | S19: =RANDBETWEEN(0,10) -> 0 | T19: =RANDBETWEEN(0,10) -> 2 | U19: =RANDBETWEEN(10,30) -> 26 | V19: =W19+X19+Y19 -> 6 | W19: =RANDBETWEEN(0,2) -> 2 | X19: =RANDBETWEEN(0,2) -> 2 | Y19: =RANDBETWEEN(0,2) -> 2 | Z19: =AA19+AB19 -> 1 | AA19: =RANDBETWEEN(0,2) -> 1 | AB19: =RANDBETWEEN(0,2) -> 0 | AC19: =RANDBETWEEN(0,2) -> 2 | AD19: =RANDBETWEEN(0,2) -> 2 | AE19: =RANDBETWEEN(0,2) -> 1 | AF19: =RANDBETWEEN(0,2) -> 0 | AG19: =SUM(AC19:AF19) -> 5 | AH19: =RANDBETWEEN(1,10) -> 4 | AI19: =RANDBETWEEN(1,10) -> 6 | AJ19: =RANDBETWEEN(1,10) -> 7 | AK19: =SUM(AH19:AJ19) -> 17 | AY19: =RANDBETWEEN(1,10)/10 -> 0.9 | AZ19: =RANDBETWEEN(1,10)/10 -> 0.8 | BA19: 0 | BB19: 0 | BC19: 1200 | BD19: 1200
A20: =A19 -> 46254 | B20: Покровський н. | C20: =SUM(D20,F20) -> 3 | D20: =RANDBETWEEN(0,2) -> 2 | E20: =RANDBETWEEN(0,2) -> 1 | F20: =RANDBETWEEN(0,2) -> 1 | G20: =RANDBETWEEN(0,2) -> 2 | H20: =RANDBETWEEN(0,2) -> 1 | I20: =RANDBETWEEN(0,2) -> 0 | J20: =RANDBETWEEN(0,2) -> 0 | K20: =RANDBETWEEN(0,2) -> 1 | L20: =RANDBETWEEN(0,2) -> 2 | M20: =SUM(N20:T20) -> 31 | N20: =RANDBETWEEN(0,10) -> 10 | O20: =RANDBETWEEN(0,10) -> 1 | P20: =RANDBETWEEN(0,10) -> 1 | Q20: =RANDBETWEEN(0,10) -> 0 | R20: =RANDBETWEEN(0,10) -> 8 | S20: =RANDBETWEEN(0,10) -> 5 | T20: =RANDBETWEEN(0,10) -> 6 | U20: =RANDBETWEEN(10,30) -> 26 | V20: =W20+X20+Y20 -> 3 | W20: =RANDBETWEEN(0,2) -> 1 | X20: =RANDBETWEEN(0,2) -> 2 | Y20: =RANDBETWEEN(0,2) -> 0 | Z20: =AA20+AB20 -> 3 | AA20: =RANDBETWEEN(0,2) -> 2 | AB20: =RANDBETWEEN(0,2) -> 1 | AC20: =RANDBETWEEN(0,2) -> 2 | AD20: =RANDBETWEEN(0,2) -> 0 | AE20: =RANDBETWEEN(0,2) -> 2 | AF20: =RANDBETWEEN(0,2) -> 2 | AG20: =SUM(AC20:AF20) -> 6 | AH20: =RANDBETWEEN(1,10) -> 4 | AI20: =RANDBETWEEN(1,10) -> 3 | AJ20: =RANDBETWEEN(1,10) -> 2 | AK20: =SUM(AH20:AJ20) -> 9 | AY20: =RANDBETWEEN(1,10)/10 -> 0.2 | AZ20: =RANDBETWEEN(1,10)/10 -> 0.5 | BA20: 0 | BB20: 0 | BC20: 1200 | BD20: 1200
A21: =A20 -> 46254 | B21: 9 АК | C21: =SUM(D21,F21) -> 4 | D21: =RANDBETWEEN(0,2) -> 2 | E21: =RANDBETWEEN(0,2) -> 0 | F21: =RANDBETWEEN(0,2) -> 2 | G21: =RANDBETWEEN(0,2) -> 1 | H21: =RANDBETWEEN(0,2) -> 2 | I21: =RANDBETWEEN(0,2) -> 0 | J21: =RANDBETWEEN(0,2) -> 1 | K21: =RANDBETWEEN(0,2) -> 0 | L21: =RANDBETWEEN(0,2) -> 1 | M21: =SUM(N21:T21) -> 29 | N21: =RANDBETWEEN(0,10) -> 1 | O21: =RANDBETWEEN(0,10) -> 8 | P21: =RANDBETWEEN(0,10) -> 0 | Q21: =RANDBETWEEN(0,10) -> 4 | R21: =RANDBETWEEN(0,10) -> 4 | S21: =RANDBETWEEN(0,10) -> 3 | T21: =RANDBETWEEN(0,10) -> 9 | U21: =RANDBETWEEN(10,30) -> 15 | V21: =W21+X21+Y21 -> 4 | W21: =RANDBETWEEN(0,2) -> 2 | X21: =RANDBETWEEN(0,2) -> 1 | Y21: =RANDBETWEEN(0,2) -> 1 | Z21: =AA21+AB21 -> 2 | AA21: =RANDBETWEEN(0,2) -> 2 | AB21: =RANDBETWEEN(0,2) -> 0 | AC21: =RANDBETWEEN(0,2) -> 2 | AD21: =RANDBETWEEN(0,2) -> 0 | AE21: =RANDBETWEEN(0,2) -> 2 | AF21: =RANDBETWEEN(0,2) -> 0 | AG21: =SUM(AC21:AF21) -> 4 | AH21: =RANDBETWEEN(1,10) -> 6 | AI21: =RANDBETWEEN(1,10) -> 5 | AJ21: =RANDBETWEEN(1,10) -> 2 | AK21: =SUM(AH21:AJ21) -> 13 | AY21: =RANDBETWEEN(1,10)/10 -> 0.8 | AZ21: =RANDBETWEEN(1,10)/10 -> 0.9 | BA21: 0 | BB21: 0 | BC21: 1200 | BD21: 1200
A22: =A21 -> 46254 | B22: УВ (с) "Схід" | C22: =SUM(D22,F22) -> 20 | D22: =SUM(D16:D21) -> 9 | E22: =SUM(E16:E21) -> 3 | F22: =SUM(F16:F21) -> 11 | G22: =SUM(G16:G21) -> 9 | H22: =SUM(H16:H21) -> 5 | I22: =SUM(I16:I21) -> 3 | J22: =SUM(J16:J21) -> 5 | K22: =SUM(K16:K21) -> 6 | ... U22: =SUM(U16:U21) -> 140 | V22: =W22+X22+Y22 -> 22 | W22: =SUM(W16:W21) -> 10 | X22: =SUM(X16:X21) -> 6 | Y22: =SUM(Y16:Y21) -> 6 | Z22: =AA22+AB22 -> 7 | AA22: =SUM(AA16:AA21) -> 5 | AB22: =SUM(AB16:AB21) -> 2 | AC22: =SUM(AC16:AC21) -> 7 | AD22: =SUM(AD16:AD21) -> 4 | AE22: =SUM(AE16:AE21) -> 9 | AF22: =SUM(AF16:AF21) -> 3 | AG22: =SUM(AC22:AF22) -> 23 | AH22: =SUM(AH16:AH21) -> 35 | AI22: =SUM(AI16:AI21) -> 25 | AJ22: =SUM(AJ16:AJ21) -> 32 | AK22: =SUM(AH22:AJ22) -> 92 | AY22: =SUM(AY16:AY21) -> 3 | AZ22: =SUM(AZ16:AZ21) -> 4 | BA22: =SUM(BA16:BA21) -> 0 | BB22: =SUM(BB16:BB21) -> 0 | BC22: =SUM(BC16:BC21) -> 7200 | BD22: =SUM(BD16:BD21) -> 7200 | BE22: =TEXTJOIN(", ",TRUE,BE16:BE21) | BF22: =TEXTJOIN(", ",TRUE,BF16:BF21)
A23: =A22 -> 46254 | B23: 20 АК | C23: =SUM(D23,F23) -> 2 | D23: =RANDBETWEEN(0,2) -> 0 | E23: =RANDBETWEEN(0,2) -> 0 | F23: =RANDBETWEEN(0,2) -> 2 | G23: =RANDBETWEEN(0,2) -> 1 | H23: =RANDBETWEEN(0,2) -> 2 | I23: =RANDBETWEEN(0,2) -> 2 | J23: =RANDBETWEEN(0,2) -> 0 | K23: =RANDBETWEEN(0,2) -> 1 | L23: =RANDBETWEEN(0,2) -> 2 | M23: =SUM(N23:T23) -> 36 | N23: =RANDBETWEEN(0,10) -> 0 | O23: =RANDBETWEEN(0,10) -> 10 | P23: =RANDBETWEEN(0,10) -> 6 | Q23: =RANDBETWEEN(0,10) -> 8 | R23: =RANDBETWEEN(0,10) -> 0 | S23: =RANDBETWEEN(0,10) -> 9 | T23: =RANDBETWEEN(0,10) -> 3 | U23: =RANDBETWEEN(10,30) -> 14 | V23: =W23+X23+Y23 -> 2 | W23: =RANDBETWEEN(0,2) -> 0 | X23: =RANDBETWEEN(0,2) -> 2 | Y23: =RANDBETWEEN(0,2) -> 0 | Z23: =AA23+AB23 -> 1 | AA23: =RANDBETWEEN(0,2) -> 1 | AB23: =RANDBETWEEN(0,2) -> 0 | AC23: =RANDBETWEEN(0,2) -> 1 | AD23: =RANDBETWEEN(0,2) -> 2 | AE23: =RANDBETWEEN(0,2) -> 2 | AF23: =RANDBETWEEN(0,2) -> 1 | AG23: =SUM(AC23:AF23) -> 6 | AH23: =RANDBETWEEN(1,10) -> 10 | AI23: =RANDBETWEEN(1,10) -> 7 | AJ23: =RANDBETWEEN(1,10) -> 5 | AK23: =SUM(AH23:AJ23) -> 22 | AY23: =RANDBETWEEN(1,10)/10 -> 0.4 | AZ23: =RANDBETWEEN(1,10)/10 -> 0.4 | BA23: 0 | BB23: 0 | BC23: 1200 | BD23: 1200
A24: =A23 -> 46254 | B24: Олександрівський н. | C24: =SUM(D24,F24) -> 2 | D24: =RANDBETWEEN(0,2) -> 2 | E24: =RANDBETWEEN(0,2) -> 2 | F24: =RANDBETWEEN(0,2) -> 0 | G24: =RANDBETWEEN(0,2) -> 0 | H24: =RANDBETWEEN(0,2) -> 1 | I24: =RANDBETWEEN(0,2) -> 0 | J24: =RANDBETWEEN(0,2) -> 2 | K24: =RANDBETWEEN(0,2) -> 2 | L24: =RANDBETWEEN(0,2) -> 0 | M24: =SUM(N24:T24) -> 34 | N24: =RANDBETWEEN(0,10) -> 9 | O24: =RANDBETWEEN(0,10) -> 5 | P24: =RANDBETWEEN(0,10) -> 6 | Q24: =RANDBETWEEN(0,10) -> 2 | R24: =RANDBETWEEN(0,10) -> 1 | S24: =RANDBETWEEN(0,10) -> 1 | T24: =RANDBETWEEN(0,10) -> 10 | U24: =RANDBETWEEN(10,30) -> 23 | V24: =W24+X24+Y24 -> 4 | W24: =RANDBETWEEN(0,2) -> 1 | X24: =RANDBETWEEN(0,2) -> 2 | Y24: =RANDBETWEEN(0,2) -> 1 | Z24: =AA24+AB24 -> 3 | AA24: =RANDBETWEEN(0,2) -> 2 | AB24: =RANDBETWEEN(0,2) -> 1 | AC24: =RANDBETWEEN(0,2) -> 1 | AD24: =RANDBETWEEN(0,2) -> 2 | AE24: =RANDBETWEEN(0,2) -> 0 | AF24: =RANDBETWEEN(0,2) -> 0 | AG24: =SUM(AC24:AF24) -> 3 | AH24: =RANDBETWEEN(1,10) -> 4 | AI24: =RANDBETWEEN(1,10) -> 9 | AJ24: =RANDBETWEEN(1,10) -> 3 | AK24: =SUM(AH24:AJ24) -> 16 | AY24: =RANDBETWEEN(1,10)/10 -> 0.3 | AZ24: =RANDBETWEEN(1,10)/10 -> 0.7 | BA24: 0 | BB24: 0 | BC24: 1200 | BD24: 1200
A25: =A24 -> 46254 | B25: 17 АК | C25: =SUM(D25,F25) -> 0 | D25: =RANDBETWEEN(0,2) -> 0 | E25: =RANDBETWEEN(0,2) -> 2 | F25: =RANDBETWEEN(0,2) -> 0 | G25: =RANDBETWEEN(0,2) -> 0 | H25: =RANDBETWEEN(0,2) -> 2 | I25: =RANDBETWEEN(0,2) -> 1 | J25: =RANDBETWEEN(0,2) -> 0 | K25: =RANDBETWEEN(0,2) -> 1 | L25: =RANDBETWEEN(0,2) -> 1 | M25: =SUM(N25:T25) -> 40 | N25: =RANDBETWEEN(0,10) -> 8 | O25: =RANDBETWEEN(0,10) -> 6 | P25: =RANDBETWEEN(0,10) -> 2 | Q25: =RANDBETWEEN(0,10) -> 3 | R25: =RANDBETWEEN(0,10) -> 7 | S25: =RANDBETWEEN(0,10) -> 9 | T25: =RANDBETWEEN(0,10) -> 5 | U25: =RANDBETWEEN(10,30) -> 20 | V25: =W25+X25+Y25 -> 2 | W25: =RANDBETWEEN(0,2) -> 1 | X25: =RANDBETWEEN(0,2) -> 1 | Y25: =RANDBETWEEN(0,2) -> 0 | Z25: =AA25+AB25 -> 2 | AA25: =RANDBETWEEN(0,2) -> 1 | AB25: =RANDBETWEEN(0,2) -> 1 | AC25: =RANDBETWEEN(0,2) -> 0 | AD25: =RANDBETWEEN(0,2) -> 1 | AE25: =RANDBETWEEN(0,2) -> 1 | AF25: =RANDBETWEEN(0,2) -> 0 | AG25: =SUM(AC25:AF25) -> 2 | AH25: =RANDBETWEEN(1,10) -> 4 | AI25: =RANDBETWEEN(1,10) -> 10 | AJ25: =RANDBETWEEN(1,10) -> 1 | AK25: =SUM(AH25:AJ25) -> 15 | AY25: =RANDBETWEEN(1,10)/10 -> 0.3 | AZ25: =RANDBETWEEN(1,10)/10 -> 0.2 | BA25: 0 | BB25: 0 | BC25: 1200 | BD25: 1200
A26: =A25 -> 46254 | B26: 30 КМП | C26: =SUM(D26,F26) -> 1 | D26: =RANDBETWEEN(0,2) -> 1 | E26: =RANDBETWEEN(0,2) -> 0 | F26: =RANDBETWEEN(0,2) -> 0 | G26: =RANDBETWEEN(0,2) -> 0 | H26: =RANDBETWEEN(0,2) -> 2 | I26: =RANDBETWEEN(0,2) -> 1 | J26: =RANDBETWEEN(0,2) -> 2 | K26: =RANDBETWEEN(0,2) -> 2 | L26: =RANDBETWEEN(0,2) -> 1 | M26: =SUM(N26:T26) -> 49 | N26: =RANDBETWEEN(0,10) -> 7 | O26: =RANDBETWEEN(0,10) -> 8 | P26: =RANDBETWEEN(0,10) -> 9 | Q26: =RANDBETWEEN(0,10) -> 10 | R26: =RANDBETWEEN(0,10) -> 2 | S26: =RANDBETWEEN(0,10) -> 8 | T26: =RANDBETWEEN(0,10) -> 5 | U26: =RANDBETWEEN(10,30) -> 10 | V26: =W26+X26+Y26 -> 3 | W26: =RANDBETWEEN(0,2) -> 1 | X26: =RANDBETWEEN(0,2) -> 2 | Y26: =RANDBETWEEN(0,2) -> 0 | Z26: =AA26+AB26 -> 4 | AA26: =RANDBETWEEN(0,2) -> 2 | AB26: =RANDBETWEEN(0,2) -> 2 | AC26: =RANDBETWEEN(0,2) -> 1 | AD26: =RANDBETWEEN(0,2) -> 0 | AE26: =RANDBETWEEN(0,2) -> 1 | AF26: =RANDBETWEEN(0,2) -> 0 | AG26: =SUM(AC26:AF26) -> 2 | AH26: =RANDBETWEEN(1,10) -> 9 | AI26: =RANDBETWEEN(1,10) -> 4 | AJ26: =RANDBETWEEN(1,10) -> 9 | AK26: =SUM(AH26:AJ26) -> 22 | AY26: =RANDBETWEEN(1,10)/10 -> 0.3 | AZ26: =RANDBETWEEN(1,10)/10 -> 0.1 | BA26: 0 | BB26: 0 | BC26: 1200 | BD26: 1200
A27: =A26 -> 46254 | B27: ОТУ "Одеса" | C27: =SUM(D27,F27) -> 1 | D27: =RANDBETWEEN(0,2) -> 1 | E27: =RANDBETWEEN(0,2) -> 2 | F27: =RANDBETWEEN(0,2) -> 0 | G27: =RANDBETWEEN(0,2) -> 1 | H27: =RANDBETWEEN(0,2) -> 0 | I27: =RANDBETWEEN(0,2) -> 2 | J27: =RANDBETWEEN(0,2) -> 2 | K27: =RANDBETWEEN(0,2) -> 1 | L27: =RANDBETWEEN(0,2) -> 2 | M27: =SUM(N27:T27) -> 29 | N27: =RANDBETWEEN(0,10) -> 0 | O27: =RANDBETWEEN(0,10) -> 8 | P27: =RANDBETWEEN(0,10) -> 0 | Q27: =RANDBETWEEN(0,10) -> 4 | R27: =RANDBETWEEN(0,10) -> 4 | S27: =RANDBETWEEN(0,10) -> 9 | T27: =RANDBETWEEN(0,10) -> 4 | U27: =RANDBETWEEN(10,30) -> 14 | V27: =W27+X27+Y27 -> 2 | W27: =RANDBETWEEN(0,2) -> 1 | X27: =RANDBETWEEN(0,2) -> 1 | Y27: =RANDBETWEEN(0,2) -> 0 | Z27: =AA27+AB27 -> 1 | AA27: =RANDBETWEEN(0,2) -> 1 | AB27: =RANDBETWEEN(0,2) -> 0 | AC27: =RANDBETWEEN(0,2) -> 0 | AD27: =RANDBETWEEN(0,2) -> 1 | AE27: =RANDBETWEEN(0,2) -> 2 | AF27: =RANDBETWEEN(0,2) -> 1 | AG27: =SUM(AC27:AF27) -> 4 | AH27: =RANDBETWEEN(1,10) -> 6 | AI27: =RANDBETWEEN(1,10) -> 10 | AJ27: =RANDBETWEEN(1,10) -> 1 | AK27: =SUM(AH27:AJ27) -> 17 | AY27: =RANDBETWEEN(1,10)/10 -> 0.6 | AZ27: =RANDBETWEEN(1,10)/10 -> 0.8 | BA27: 0 | BB27: 0 | BC27: 1200 | BD27: 1200
A28: =A27 -> 46254 | B28: УВ (с) "Південь" | C28: =SUM(D28,F28) -> 6 | D28: =SUM(D23:D27) -> 4 | E28: =SUM(E23:E27) -> 6 | F28: =SUM(F23:F27) -> 2 | G28: =SUM(G23:G27) -> 2 | H28: =SUM(H23:H27) -> 7 | I28: =SUM(I23:I27) -> 6 | J28: =SUM(J23:J27) -> 6 | K28: =SUM(K23:K27) -> 7 | L28: =SUM(L23:L27) -> 6 | M28: =SUM(N28:T28) -> 188 | N28: =SUM(N23:N27) -> 24 | O28: =SUM(O23:O27) -> 37 | P28: =SUM(P23:P27) -> 23 | Q28: =SUM(Q23:Q27) -> 27 | R28: =SUM(R23:R27) -> 14 | S28: =SUM(S23:S27) -> 36 | T28: =SUM(T23:T27) -> 27 | U28: =SUM(U23:U27) -> 81 | V28: =W28+X28+Y28 -> 13 | W28: =SUM(W23:W27) -> 4 | X28: =SUM(X23:X27) -> 8 | Y28: =SUM(Y23:Y27) -> 1 | Z28: =SUM(AA28:AB28) -> 11 | AA28: =SUM(AA23:AA27) -> 7 | AB28: =SUM(AB23:AB27) -> 4 | AC28: =SUM(AC23:AC27) -> 3 | AD28: =SUM(AD23:AD27) -> 6 | AE28: =SUM(AE23:AE27) -> 6 | AF28: =SUM(AF23:AF27) -> 2 | AG28: =SUM(AC28:AF28) -> 17 | AH28: =SUM(AH23:AH27) -> 33 | AI28: =SUM(AI23:AI27) -> 40 | AJ28: =SUM(AJ23:AJ27) -> 19 | AK28: =SUM(AH28:AJ28) -> 92 | AY28: =SUM(AY23:AY27) -> 1.9 | AZ28: =SUM(AZ23:AZ27) -> 2.2 | BA28: =SUM(BA23:BA27) -> 0 | BB28: =SUM(BB23:BB27) -> 0 | BC28: =SUM(BC23:BC27) -> 6000 | BD28: =SUM(BD23:BD27) -> 6000 | BE28: =TEXTJOIN(", ",TRUE,BE23:BE27) | BF28: =TEXTJOIN(", ",TRUE,BF23:BF27)
A29: =A28 -> 46254 | B29: ВСЬОГО за СО: | C29: =SUM(C3+C4+C5+C9,C8,C15,C22,C28) -> 49 | D29: =SUM(D3+D4+D5+D9,D8,D15,D22,D28) -> 30 | E29: =SUM(E3+E4+E5+E9,E8,E15,E22,E28) -> 16 | F29: =SUM(F3+F4+F5+F9,F8,F15,F22,F28) -> 19 | G29: =SUM(G3+G4+G5+G9,G8,G15,G22,G28) -> 18 | H29: =SUM(H3+H4+H5+H9,H8,H15,H22,H28) -> 20 | I29: =SUM(I3+I4+I5+I9,I8,I15,I22,I28) -> 20 | J29: =SUM(J3+J4+J5+J9,J8,J15,J22,J28) -> 22 | ... AK29: =SUM(AK3+AK4+AK5+AK9,AK8,AK15,AK22,AK28) -> 341 | AY29: =SUM(AY3+AY4+AY5+AY9,AY8,AY15,AY22,AY28) -> 17.1 | AZ29: =SUM(AZ3+AZ4+AZ5+AZ9,AZ8,AZ15,AZ22,AZ28) -> 19.86 | BA29: =SUM(BA3+BA4+BA5+BA9,BA8,BA15,BA22,BA28) -> 5 | BB29: =SUM(BB3+BB4+BB5+BB9,BB8,BB15,BB22,BB28) -> 3 | BC29: =SUM(BC3+BC4+BC5+BC9,BC8,BC15,BC22,BC28) -> 26400 | BD29: =SUM(BD3+BD4+BD5+BD9,BD8,BD15,BD22,BD28) -> 26400 | BE29: =TEXTJOIN(", ",TRUE,BE28,BE22,BE15,BE9,BE8,BE5,BE4,BE3) -> Олександівка, Пантелеймонівка, Миколаївка, Курськ, Рильск | BF29: =TEXTJOIN(", ",TRUE,BF28,BF22,BF15,BF9,BF8,BF5,BF4,BF3) -> Загреблі, Верхні води, Ступочки
A30: =A29+1 -> 46255
A31: =A30 -> 46255 | B31: УСБпС | C31: =SUM(D31,F31) -> 1 | D31: =RANDBETWEEN(0,2) -> 1 | E31: =RANDBETWEEN(0,2) -> 0 | F31: =RANDBETWEEN(0,2) -> 0 | G31: =RANDBETWEEN(0,2) -> 0 | H31: =RANDBETWEEN(0,2) -> 2 | I31: =RANDBETWEEN(0,2) -> 1 | J31: =RANDBETWEEN(0,2) -> 2 | K31: =RANDBETWEEN(0,2) -> 2 | L31: =RANDBETWEEN(0,2) -> 1 | M31: =SUM(N31:T31) -> 30 | N31: =RANDBETWEEN(0,10) -> 3 | O31: =RANDBETWEEN(0,10) -> 10 | P31: =RANDBETWEEN(0,10) -> 7 | Q31: =RANDBETWEEN(0,10) -> 1 | R31: =RANDBETWEEN(0,10) -> 2 | S31: =RANDBETWEEN(0,10) -> 0 | T31: =RANDBETWEEN(0,10) -> 7 | U31: =RANDBETWEEN(10,30) -> 18 | V31: =SUM(W31:Y31) -> 4 | W31: =RANDBETWEEN(0,2) -> 2 | X31: =RANDBETWEEN(0,2) -> 1 | Y31: =RANDBETWEEN(0,2) -> 1 | Z31: =AA31+AB31 -> 1 | AA31: =RANDBETWEEN(0,2) -> 0 | AB31: =RANDBETWEEN(0,2) -> 1 | AC31: =RANDBETWEEN(0,2) -> 2 | AD31: =RANDBETWEEN(0,2) -> 2 | AE31: =RANDBETWEEN(0,2) -> 1 | AF31: =RANDBETWEEN(0,2) -> 2 | AG31: =SUM(AC31:AF31) -> 7 | AH31: =RANDBETWEEN(1,10) -> 2 | AI31: =RANDBETWEEN(1,10) -> 7 | AJ31: =RANDBETWEEN(1,10) -> 7 | AK31: =SUM(AH31:AJ31) -> 16 | AY31: =RANDBETWEEN(1,10)/10 -> 0.8 | AZ31: =RANDBETWEEN(1,10)/10 -> 0.7 | BA31: 0 | BB31: 0 | BC31: =SUM(BC3,'ГОЧ'!$AY31) -> 1200.8 | BD31: =SUM(BD3,'ГОЧ'!$AZ31) -> 1200.7
A32: =A31 -> 46255 | B32: УВ (с) "Захід" | C32: =SUM(D32,F32) -> 0 | D32: =RANDBETWEEN(0,2) -> 0 | E32: =RANDBETWEEN(0,2) -> 0 | F32: =RANDBETWEEN(0,2) -> 0 | G32: =RANDBETWEEN(0,2) -> 2 | H32: =RANDBETWEEN(0,2) -> 1 | I32: =RANDBETWEEN(0,2) -> 1 | J32: =RANDBETWEEN(0,2) -> 0 | K32: =RANDBETWEEN(0,2) -> 2 | L32: =RANDBETWEEN(0,2) -> 1 | M32: =SUM(N32:T32) -> 40 | N32: =RANDBETWEEN(0,10) -> 4 | O32: =RANDBETWEEN(0,10) -> 1 | P32: =RANDBETWEEN(0,10) -> 5 | Q32: =RANDBETWEEN(0,10) -> 10 | R32: =RANDBETWEEN(0,10) -> 5 | S32: =RANDBETWEEN(0,10) -> 6 | T32: =RANDBETWEEN(0,10) -> 9 | U32: =RANDBETWEEN(10,30) -> 13 | V32: =SUM(W32:Y32) -> 4 | W32: =RANDBETWEEN(0,2) -> 1 | X32: =RANDBETWEEN(0,2) -> 2 | Y32: =RANDBETWEEN(0,2) -> 1 | Z32: =AA32+AB32 -> 1 | AA32: =RANDBETWEEN(0,2) -> 1 | AB32: =RANDBETWEEN(0,2) -> 0 | AC32: =RANDBETWEEN(0,2) -> 0 | AD32: =RANDBETWEEN(0,2) -> 1 | AE32: =RANDBETWEEN(0,2) -> 1 | AF32: =RANDBETWEEN(0,2) -> 2 | AG32: =SUM(AC32:AF32) -> 4 | AH32: =RANDBETWEEN(1,10) -> 9 | AI32: =RANDBETWEEN(1,10) -> 8 | AJ32: =RANDBETWEEN(1,10) -> 1 | AK32: =SUM(AH32:AJ32) -> 18 | AY32: =RANDBETWEEN(1,10)/10 -> 0.4 | AZ32: =RANDBETWEEN(1,10)/10 -> 1 | BA32: 0 | BB32: 0 | BC32: =SUM(BC4,'ГОЧ'!$AY32) -> 1200.4 | BD32: =SUM(BD4,'ГОЧ'!$AZ32) -> 1201
A33: =A32 -> 46255 | B33: 12 АК | C33: =SUM(D33,F33) -> 0 | D33: 0 | E33: 0 | F33: 0 | G33: 0 | H33: 0 | I33: 0 | J33: 0 | K33: 0 | L33: 0 | M33: =SUM(N33:T33) -> 0 | N33: 0 | O33: 0 | P33: 0 | Q33: 0 | R33: 0 | S33: 0 | T33: 0 | U33: 0 | V33: =SUM(W33:Y33) -> 0 | W33: 0 | X33: 0 | Y33: 0 | Z33: =AA33+AB33 -> 0 | AA33: 0 | AB33: 0 | AC33: 0 | AD33: 0 | AE33: 0 | AF33: 0 | AG33: =SUM(AC33:AF33) -> 0 | AH33: 0 | AI33: 0 | AJ33: 0 | AK33: =SUM(AH33:AJ33) -> 0 | AY33: =SUM(AY31:AY32) -> 1.2 | AZ33: =SUM(AZ31:AZ32) -> 1.7 | BA33: =SUM(BA31:BA32) -> 0 | BB33: =SUM(BB31:BB32) -> 0 | BC33: =SUM(BC31:BC32) -> 2401.2 | BD33: =SUM(BD31:BD32) -> 2401.7
A34: =A33 -> 46255 | B34: 15 АК | C34: =SUM(D34,F34) -> 1 | D34: =RANDBETWEEN(0,2) -> 1 | E34: =RANDBETWEEN(0,2) -> 2 | F34: =RANDBETWEEN(0,2) -> 0 | G34: =RANDBETWEEN(0,2) -> 0 | H34: =RANDBETWEEN(0,2) -> 1 | I34: =RANDBETWEEN(0,2) -> 1 | J34: =RANDBETWEEN(0,2) -> 1 | K34: =RANDBETWEEN(0,2) -> 1 | L34: =RANDBETWEEN(0,2) -> 0 | M34: =SUM(N34:T34) -> 33 | N34: =RANDBETWEEN(0,10) -> 5 | O34: =RANDBETWEEN(0,10) -> 7 | P34: =RANDBETWEEN(0,10) -> 3 | Q34: =RANDBETWEEN(0,10) -> 8 | R34: =RANDBETWEEN(0,10) -> 2 | S34: =RANDBETWEEN(0,10) -> 6 | T34: =RANDBETWEEN(0,10) -> 2 | U34: =RANDBETWEEN(10,30) -> 20 | V34: =SUM(W34:Y34) -> 3 | W34: =RANDBETWEEN(0,2) -> 1 | X34: =RANDBETWEEN(0,2) -> 1 | Y34: =RANDBETWEEN(0,2) -> 1 | Z34: =SUM(AA34:AB34) -> 3 | AA34: =RANDBETWEEN(0,2) -> 1 | AB34: =RANDBETWEEN(0,2) -> 2 | AC34: =RANDBETWEEN(0,2) -> 1 | AD34: =RANDBETWEEN(0,2) -> 1 | AE34: =RANDBETWEEN(0,2) -> 2 | AF34: =RANDBETWEEN(0,2) -> 2 | AG34: =SUM(AC34:AF34) -> 6 | AH34: =RANDBETWEEN(1,10) -> 9 | AI34: =RANDBETWEEN(1,10) -> 1 | AJ34: =RANDBETWEEN(1,10) -> 4 | AK34: =SUM(AH34:AJ34) -> 14 | AY34: =RANDBETWEEN(1,10)/10 -> 0.5 | AZ34: =RANDBETWEEN(1,10)/10 -> 0.2 | BA34: 0 | BB34: 0 | BC34: =SUM(BC6,'ГОЧ'!$AY34) -> 1200.5 | BD34: =SUM(BD6,'ГОЧ'!$AZ34) -> 1200.2
A35: =A34 -> 46255 | B35: 18 АК | C35: =SUM(D35,F35) -> 1 | D35: =RANDBETWEEN(0,2) -> 0 | E35: =RANDBETWEEN(0,2) -> 1 | F35: =RANDBETWEEN(0,2) -> 1 | G35: =RANDBETWEEN(0,2) -> 2 | H35: =RANDBETWEEN(0,2) -> 2 | I35: =RANDBETWEEN(0,2) -> 1 | J35: =RANDBETWEEN(0,2) -> 1 | K35: =RANDBETWEEN(0,2) -> 2 | L35: =RANDBETWEEN(0,2) -> 2 | M35: =SUM(N35:T35) -> 39 | N35: =RANDBETWEEN(0,10) -> 6 | O35: =RANDBETWEEN(0,10) -> 5 | P35: =RANDBETWEEN(0,10) -> 5 | Q35: =RANDBETWEEN(0,10) -> 10 | R35: =RANDBETWEEN(0,10) -> 8 | S35: =RANDBETWEEN(0,10) -> 2 | T35: =RANDBETWEEN(0,10) -> 3 | U35: =RANDBETWEEN(10,30) -> 30 | V35: =SUM(W35:Y35) -> 2 | W35: =RANDBETWEEN(0,2) -> 2 | X35: =RANDBETWEEN(0,2) -> 0 | Y35: =RANDBETWEEN(0,2) -> 0 | Z35: =SUM(AA35:AB35) -> 2 | AA35: =RANDBETWEEN(0,2) -> 2 | AB35: =RANDBETWEEN(0,2) -> 0 | AC35: =RANDBETWEEN(0,2) -> 1 | AD35: =RANDBETWEEN(0,2) -> 1 | AE35: =RANDBETWEEN(0,2) -> 2 | AF35: =RANDBETWEEN(0,2) -> 1 | AG35: =SUM(AC35:AF35) -> 5 | AH35: =RANDBETWEEN(1,10) -> 5 | AI35: =RANDBETWEEN(1,10) -> 6 | AJ35: =RANDBETWEEN(1,10) -> 4 | AK35: =SUM(AH35:AJ35) -> 15 | AY35: =RANDBETWEEN(1,10)/10 -> 0.3 | AZ35: =RANDBETWEEN(1,10)/10 -> 0.7 | BA35: 0 | BB35: 0 | BC35: =SUM(BC7,'ГОЧ'!$AY35) -> 1200.3 | BD35: =SUM(BD7,'ГОЧ'!$AZ35) -> 1200.7
A36: =A35 -> 46255 | B36: УВ (с) "Північ" | C36: =SUM(D36,F36) -> 2 | D36: =SUM(D34:D35) -> 1 | E36: =SUM(E34:E35) -> 3 | F36: =SUM(F34:F35) -> 1 | G36: =SUM(G34:G35) -> 2 | H36: =SUM(H34:H35) -> 3 | I36: =SUM(I34:I35) -> 2 | J36: =SUM(J34:J35) -> 2 | K36: =SUM(K34:K35) -> 3 | L36: =SUM(L34:L35) -> 2 | M36: =SUM(N36:T36) -> 62 | N36: =SUM(N34:N35) -> 11 | O36: =SUM(O34:O35) -> 12 | P36: =SUM(P34:P35) -> 8 | Q36: =SUM(Q34:Q35) -> 18 | R36: 0 | S36: =SUM(S34:S35) -> 8 | T36: =SUM(T34:T35) -> 5 | U36: =SUM(U34:U35) -> 50 | V36: =SUM(W36:Y36) -> 5 | W36: =SUM(W34:W35) -> 3 | X36: =SUM(X34:X35) -> 1 | Y36: =SUM(Y34:Y35) -> 1 | Z36: =SUM(AA36:AB36) -> 5 | AA36: =SUM(AA34:AA35) -> 3 | AB36: =SUM(AB34:AB35) -> 2 | AC36: =SUM(AC34:AC35) -> 2 | AD36: =SUM(AD34:AD35) -> 2 | AE36: =SUM(AE34:AE35) -> 4 | AF36: =SUM(AF34:AF35) -> 3 | AG36: =SUM(AC36:AF36) -> 11 | AH36: =SUM(AH34:AH35) -> 14 | AI36: =SUM(AI34:AI35) -> 7 | AJ36: =SUM(AJ34:AJ35) -> 8 | AK36: =SUM(AH36:AJ36) -> 29 | AY36: =SUM(AY34:AY35) -> 0.8 | AZ36: =SUM(AZ34:AZ35) -> 0.9 | BA36: =SUM(BA34:BA35) -> 0 | BB36: =SUM(BB34:BB35) -> 0 | BC36: =SUM(BC34:BC35) -> 2400.8 | BD36: =SUM(BD34:BD35) -> 2400.9 | BE36: =TEXTJOIN(", ",TRUE,BE34:BE35) | BF36: =TEXTJOIN(", ",TRUE,BF34:BF35)
A37: =A36 -> 46255 | B37: УВ "Курськ" | C37: =SUM(D37,F37) -> 5 | D37: 3 | E37: 0 | F37: 2 | G37: 2 | H37: 0 | I37: 0 | J37: 1 | K37: 1 | L37: 0 | M37: =SUM(N37:T37) -> 38 | N37: 0 | O37: 0 | P37: 0 | Q37: 9 | R37: 0 | S37: 0 | T37: 29 | U37: 7 | V37: =W37+X37+Y37 -> 0 | W37: 0 | X37: 0 | Y37: 0 | Z37: =SUM(AA37:AB37) -> 0 | AA37: 0 | AB37: 0 | AC37: 0 | AD37: 1 | AE37: 0 | AF37: 0 | AG37: =SUM(AC37:AF37) -> 1 | AH37: 6 | AI37: 5 | AJ37: 0 | AK37: =SUM(AH37:AJ37) -> 11 | AY37: =RANDBETWEEN(1,10) -> 5 | AZ37: =RANDBETWEEN(1,10) -> 2 | BA37: 2 | BB37: 0 | BC37: 1 | BD37: 2 | BE37: Курськ, Рильск
A38: =A37 -> 46255 | B38: 14 АК | C38: =SUM(D38,F38) -> 1 | D38: =RANDBETWEEN(0,2) -> 1 | E38: =RANDBETWEEN(0,2) -> 2 | F38: =RANDBETWEEN(0,2) -> 0 | G38: =RANDBETWEEN(0,2) -> 0 | H38: =RANDBETWEEN(0,2) -> 1 | I38: =RANDBETWEEN(0,2) -> 1 | J38: =RANDBETWEEN(0,2) -> 1 | K38: =RANDBETWEEN(0,2) -> 1 | L38: =RANDBETWEEN(0,2) -> 1 | M38: =SUM(N38:T38) -> 42 | N38: =RANDBETWEEN(0,10) -> 9 | O38: =RANDBETWEEN(0,10) -> 9 | P38: =RANDBETWEEN(0,10) -> 4 | Q38: =RANDBETWEEN(0,10) -> 4 | R38: =RANDBETWEEN(0,10) -> 5 | S38: =RANDBETWEEN(0,10) -> 2 | T38: =RANDBETWEEN(0,10) -> 9 | U38: =RANDBETWEEN(10,30) -> 28 | V38: =W38+X38+Y38 -> 3 | W38: =RANDBETWEEN(0,2) -> 1 | X38: =RANDBETWEEN(0,2) -> 1 | Y38: =RANDBETWEEN(0,2) -> 1 | Z38: =AA38+AB38 -> 4 | AA38: =RANDBETWEEN(0,2) -> 2 | AB38: =RANDBETWEEN(0,2) -> 2 | AC38: =RANDBETWEEN(0,2) -> 0 | AD38: =RANDBETWEEN(0,2) -> 2 | AE38: =RANDBETWEEN(0,2) -> 2 | AF38: =RANDBETWEEN(0,2) -> 1 | AG38: =SUM(AC38:AF38) -> 5 | AH38: =RANDBETWEEN(1,10) -> 7 | AI38: =RANDBETWEEN(1,10) -> 3 | AJ38: =RANDBETWEEN(1,10) -> 8 | AK38: =SUM(AH38:AJ38) -> 18 | AY38: =RANDBETWEEN(1,10)/10 -> 0.9 | AZ38: =RANDBETWEEN(1,10)/10 -> 0.7 | BA38: 1 | BB38: 0 | BC38: =SUM(BC10,'ГОЧ'!$AY38) -> 1200.9 | BD38: =SUM(BD10,'ГОЧ'!$AZ38) -> 1200.7 | BE38: Олександівка
A39: =A38 -> 46255 | B39: 2 КНГУ "Хартія" | C39: =SUM(D39,F39) -> 4 | D39: =RANDBETWEEN(0,2) -> 2 | E39: =RANDBETWEEN(0,2) -> 1 | F39: =RANDBETWEEN(0,2) -> 2 | G39: =RANDBETWEEN(0,2) -> 1 | H39: =RANDBETWEEN(0,2) -> 2 | I39: =RANDBETWEEN(0,2) -> 2 | J39: =RANDBETWEEN(0,2) -> 2 | K39: =RANDBETWEEN(0,2) -> 0 | L39: =RANDBETWEEN(0,2) -> 2 | M39: =SUM(N39:T39) -> 38 | N39: =RANDBETWEEN(0,10) -> 10 | O39: =RANDBETWEEN(0,10) -> 5 | P39: =RANDBETWEEN(0,10) -> 4 | Q39: =RANDBETWEEN(0,10) -> 7 | R39: =RANDBETWEEN(0,10) -> 1 | S39: =RANDBETWEEN(0,10) -> 7 | T39: =RANDBETWEEN(0,10) -> 4 | U39: =RANDBETWEEN(10,30) -> 16 | V39: =W39+X39+Y39 -> 3 | W39: =RANDBETWEEN(0,2) -> 0 | X39: =RANDBETWEEN(0,2) -> 2 | Y39: =RANDBETWEEN(0,2) -> 1 | Z39: =AA39+AB39 -> 3 | AA39: =RANDBETWEEN(0,2) -> 1 | AB39: =RANDBETWEEN(0,2) -> 2 | AC39: =RANDBETWEEN(0,2) -> 0 | AD39: =RANDBETWEEN(0,2) -> 2 | AE39: =RANDBETWEEN(0,2) -> 1 | AF39: =RANDBETWEEN(0,2) -> 0 | AG39: =SUM(AC39:AF39) -> 3 | AH39: =RANDBETWEEN(1,10) -> 8 | AI39: =RANDBETWEEN(1,10) -> 10 | AJ39: =RANDBETWEEN(1,10) -> 8 | AK39: =SUM(AH39:AJ39) -> 26 | AY39: =RANDBETWEEN(1,10)/10 -> 0.8 | AZ39: =RANDBETWEEN(1,10)/10 -> 0.5 | BA39: 1 | BB39: 2 | BC39: =SUM(BC11,'ГОЧ'!$AY39) -> 1200.8 | BD39: =SUM(BD11,'ГОЧ'!$AZ39) -> 1200.5 | BE39: Пантелеймонівка | BF39: Загреблі, Верхні води
A40: =A39 -> 46255 | B40: 16 АК | C40: =SUM(D40,F40) -> 2 | D40: =RANDBETWEEN(0,2) -> 0 | E40: =RANDBETWEEN(0,2) -> 0 | F40: =RANDBETWEEN(0,2) -> 2 | G40: =RANDBETWEEN(0,2) -> 2 | H40: =RANDBETWEEN(0,2) -> 2 | I40: =RANDBETWEEN(0,2) -> 1 | J40: =RANDBETWEEN(0,2) -> 2 | K40: =RANDBETWEEN(0,2) -> 1 | L40: =RANDBETWEEN(0,2) -> 0 | M40: =SUM(N40:T40) -> 39 | N40: =RANDBETWEEN(0,10) -> 0 | O40: =RANDBETWEEN(0,10) -> 4 | P40: =RANDBETWEEN(0,10) -> 7 | Q40: =RANDBETWEEN(0,10) -> 7 | R40: =RANDBETWEEN(0,10) -> 7 | S40: =RANDBETWEEN(0,10) -> 10 | T40: =RANDBETWEEN(0,10) -> 4 | U40: =RANDBETWEEN(10,30) -> 11 | V40: =W40+X40+Y40 -> 2 | W40: =RANDBETWEEN(0,2) -> 0 | X40: =RANDBETWEEN(0,2) -> 0 | Y40: =RANDBETWEEN(0,2) -> 2 | Z40: =AA40+AB40 -> 2 | AA40: =RANDBETWEEN(0,2) -> 1 | AB40: =RANDBETWEEN(0,2) -> 1 | AC40: =RANDBETWEEN(0,2) -> 1 | AD40: =RANDBETWEEN(0,2) -> 2 | AE40: =RANDBETWEEN(0,2) -> 1 | AF40: =RANDBETWEEN(0,2) -> 2 | AG40: =SUM(AC40:AF40) -> 6 | AH40: =RANDBETWEEN(1,10) -> 6 | AI40: =RANDBETWEEN(1,10) -> 6 | AJ40: =RANDBETWEEN(1,10) -> 7 | AK40: =SUM(AH40:AJ40) -> 19 | AY40: =RANDBETWEEN(1,10)/10 -> 0.2 | AZ40: =RANDBETWEEN(1,10)/10 -> 0.3 | BA40: 0 | BB40: 0 | BC40: =SUM(BC12,'ГОЧ'!$AY40) -> 1200.2 | BD40: =SUM(BD12,'ГОЧ'!$AZ40) -> 1200.3
...

Sheet Втрати ЗСУ
A1: Дата | B1: Угруповання | C1: безповоротні_доба | D1: санітарні_доба | E1: полон_доба | F1: зниклі_безвісті_доба | G1: ВСЬОГО_доба | H1: безповоротні_рік | I1: санітарні_рік | J1: полон_рік | K1: зниклі_безвісті_рік | L1: ВСЬОГО_рік | M1: безповоротні_всього | N1: санітарні_всього | O1: полон_всього | P1: зниклі_безвісті_всього | Q1: ВСЬОГО_всього
A2: 46022 | B2: ВСЬОГО за СО: | C2: =RANDBETWEEN(1,10) -> 9 | D2: =RANDBETWEEN(1,10) -> 1 | E2: =RANDBETWEEN(1,10) -> 10 | F2: =RANDBETWEEN(1,10) -> 5 | M2: 10000 | N2: 11000 | O2: 9000 | P2: 8000 | Q2: =SUM('Втрати ЗСУ'!$M2:$P2) -> 38000
A3: 46023 | B3: ВСЬОГО за СО: | C3: =RANDBETWEEN(1,10) -> 2 | D3: =RANDBETWEEN(1,10) -> 6 | E3: =RANDBETWEEN(1,10) -> 8 | F3: =RANDBETWEEN(1,10) -> 2 | G3: =SUM('Втрати ЗСУ'!$C3:$F3) -> 18 | H3: =H2+'Втрати ЗСУ'!$C3 -> 2 | I3: =I2+'Втрати ЗСУ'!$D3 -> 6 | J3: =J2+'Втрати ЗСУ'!$E3 -> 8 | K3: =K2+'Втрати ЗСУ'!$F3 -> 2 | L3: =SUM('Втрати ЗСУ'!$H3:$K3) -> 18 | M3: =M2+'Втрати ЗСУ'!$C3 -> 10002 | N3: =N2+'Втрати ЗСУ'!$D3 -> 11006 | O3: =O2+'Втрати ЗСУ'!$E3 -> 9008 | P3: =P2+'Втрати ЗСУ'!$F3 -> 8002 | Q3: =SUM('Втрати ЗСУ'!$M3:$P3) -> 38018
A4: 46024 | B4: ВСЬОГО за СО: | C4: =RANDBETWEEN(1,10) -> 10 | D4: =RANDBETWEEN(1,10) -> 9 | E4: =RANDBETWEEN(1,10) -> 9 | F4: =RANDBETWEEN(1,10) -> 10 | G4: =SUM('Втрати ЗСУ'!$C4:$F4) -> 38 | H4: =H3+'Втрати ЗСУ'!$C4 -> 12 | I4: =I3+'Втрати ЗСУ'!$D4 -> 15 | J4: =J3+'Втрати ЗСУ'!$E4 -> 17 | K4: =K3+'Втрати ЗСУ'!$F4 -> 12 | L4: =SUM('Втрати ЗСУ'!$H4:$K4) -> 56 | M4: =M3+'Втрати ЗСУ'!$C4 -> 10012 | N4: =N3+'Втрати ЗСУ'!$D4 -> 11015 | O4: =O3+'Втрати ЗСУ'!$E4 -> 9017 | P4: =P3+'Втрати ЗСУ'!$F4 -> 8012 | Q4: =SUM('Втрати ЗСУ'!$M4:$P4) -> 38056
A5: 46025 | B5: ВСЬОГО за СО: | C5: =RANDBETWEEN(1,10) -> 1 | D5: =RANDBETWEEN(1,10) -> 8 | E5: =RANDBETWEEN(1,10) -> 1 | F5: =RANDBETWEEN(1,10) -> 3 | G5: =SUM('Втрати ЗСУ'!$C5:$F5) -> 13 | H5: =H4+'Втрати ЗСУ'!$C5 -> 13 | I5: =I4+'Втрати ЗСУ'!$D5 -> 23 | J5: =J4+'Втрати ЗСУ'!$E5 -> 18 | K5: =K4+'Втрати ЗСУ'!$F5 -> 15 | L5: =SUM('Втрати ЗСУ'!$H5:$K5) -> 69 | M5: =M4+'Втрати ЗСУ'!$C5 -> 10013 | N5: =N4+'Втрати ЗСУ'!$D5 -> 11023 | O5: =O4+'Втрати ЗСУ'!$E5 -> 9018 | P5: =P4+'Втрати ЗСУ'!$F5 -> 8015 | Q5: =SUM('Втрати ЗСУ'!$M5:$P5) -> 38069
A6: 46026 | B6: ВСЬОГО за СО: | C6: =RANDBETWEEN(1,10) -> 5 | D6: =RANDBETWEEN(1,10) -> 3 | E6: =RANDBETWEEN(1,10) -> 6 | F6: =RANDBETWEEN(1,10) -> 3 | G6: =SUM('Втрати ЗСУ'!$C6:$F6) -> 17 | H6: =H5+'Втрати ЗСУ'!$C6 -> 18 | I6: =I5+'Втрати ЗСУ'!$D6 -> 26 | J6: =J5+'Втрати ЗСУ'!$E6 -> 24 | K6: =K5+'Втрати ЗСУ'!$F6 -> 18 | L6: =SUM('Втрати ЗСУ'!$H6:$K6) -> 86 | M6: =M5+'Втрати ЗСУ'!$C6 -> 10018 | N6: =N5+'Втрати ЗСУ'!$D6 -> 11026 | O6: =O5+'Втрати ЗСУ'!$E6 -> 9024 | P6: =P5+'Втрати ЗСУ'!$F6 -> 8018 | Q6: =SUM('Втрати ЗСУ'!$M6:$P6) -> 38086
A7: 46027 | B7: ВСЬОГО за СО: | C7: =RANDBETWEEN(1,10) -> 7 | D7: =RANDBETWEEN(1,10) -> 3 | E7: =RANDBETWEEN(1,10) -> 1 | F7: =RANDBETWEEN(1,10) -> 10 | G7: =SUM('Втрати ЗСУ'!$C7:$F7) -> 21 | H7: =H6+'Втрати ЗСУ'!$C7 -> 25 | I7: =I6+'Втрати ЗСУ'!$D7 -> 29 | J7: =J6+'Втрати ЗСУ'!$E7 -> 25 | K7: =K6+'Втрати ЗСУ'!$F7 -> 28 | L7: =SUM('Втрати ЗСУ'!$H7:$K7) -> 107 | M7: =M6+'Втрати ЗСУ'!$C7 -> 10025 | N7: =N6+'Втрати ЗСУ'!$D7 -> 11029 | O7: =O6+'Втрати ЗСУ'!$E7 -> 9025 | P7: =P6+'Втрати ЗСУ'!$F7 -> 8028 | Q7: =SUM('Втрати ЗСУ'!$M7:$P7) -> 38107
A8: 46028 | B8: ВСЬОГО за СО: | C8: =RANDBETWEEN(1,10) -> 9 | D8: =RANDBETWEEN(1,10) -> 1 | E8: =RANDBETWEEN(1,10) -> 1 | F8: =RANDBETWEEN(1,10) -> 3 | G8: =SUM('Втрати ЗСУ'!$C8:$F8) -> 14 | H8: =H7+'Втрати ЗСУ'!$C8 -> 34 | I8: =I7+'Втрати ЗСУ'!$D8 -> 30 | J8: =J7+'Втрати ЗСУ'!$E8 -> 26 | K8: =K7+'Втрати ЗСУ'!$F8 -> 31 | L8: =SUM('Втрати ЗСУ'!$H8:$K8) -> 121 | M8: =M7+'Втрати ЗСУ'!$C8 -> 10034 | N8: =N7+'Втрати ЗСУ'!$D8 -> 11030 | O8: =O7+'Втрати ЗСУ'!$E8 -> 9026 | P8: =P7+'Втрати ЗСУ'!$F8 -> 8031 | Q8: =SUM('Втрати ЗСУ'!$M8:$P8) -> 38121
A9: 46029 | B9: ВСЬОГО за СО: | C9: =RANDBETWEEN(1,10) -> 7 | D9: =RANDBETWEEN(1,10) -> 2 | E9: =RANDBETWEEN(1,10) -> 10 | F9: =RANDBETWEEN(1,10) -> 10 | G9: =SUM('Втрати ЗСУ'!$C9:$F9) -> 29 | H9: =H8+'Втрати ЗСУ'!$C9 -> 41 | I9: =I8+'Втрати ЗСУ'!$D9 -> 32 | J9: =J8+'Втрати ЗСУ'!$E9 -> 36 | K9: =K8+'Втрати ЗСУ'!$F9 -> 41 | L9: =SUM('Втрати ЗСУ'!$H9:$K9) -> 150 | M9: =M8+'Втрати ЗСУ'!$C9 -> 10041 | N9: =N8+'Втрати ЗСУ'!$D9 -> 11032 | O9: =O8+'Втрати ЗСУ'!$E9 -> 9036 | P9: =P8+'Втрати ЗСУ'!$F9 -> 8041 | Q9: =SUM('Втрати ЗСУ'!$M9:$P9) -> 38150
A10: 46030 | B10: ВСЬОГО за СО: | C10: =RANDBETWEEN(1,10) -> 9 | D10: =RANDBETWEEN(1,10) -> 8 | E10: =RANDBETWEEN(1,10) -> 8 | F10: =RANDBETWEEN(1,10) -> 4 | G10: =SUM('Втрати ЗСУ'!$C10:$F10) -> 29 | H10: =H9+'Втрати ЗСУ'!$C10 -> 50 | I10: =I9+'Втрати ЗСУ'!$D10 -> 40 | J10: =J9+'Втрати ЗСУ'!$E10 -> 44 | K10: =K9+'Втрати ЗСУ'!$F10 -> 45 | L10: =SUM('Втрати ЗСУ'!$H10:$K10) -> 179 | M10: =M9+'Втрати ЗСУ'!$C10 -> 10050 | N10: =N9+'Втрати ЗСУ'!$D10 -> 11040 | O10: =O9+'Втрати ЗСУ'!$E10 -> 9044 | P10: =P9+'Втрати ЗСУ'!$F10 -> 8045 | Q10: =SUM('Втрати ЗСУ'!$M10:$P10) -> 38179
A11: 46031 | B11: ВСЬОГО за СО: | C11: =RANDBETWEEN(1,10) -> 7 | D11: =RANDBETWEEN(1,10) -> 1 | E11: =RANDBETWEEN(1,10) -> 10 | F11: =RANDBETWEEN(1,10) -> 1 | G11: =SUM('Втрати ЗСУ'!$C11:$F11) -> 19 | H11: =H10+'Втрати ЗСУ'!$C11 -> 57 | I11: =I10+'Втрати ЗСУ'!$D11 -> 41 | J11: =J10+'Втрати ЗСУ'!$E11 -> 54 | K11: =K10+'Втрати ЗСУ'!$F11 -> 46 | L11: =SUM('Втрати ЗСУ'!$H11:$K11) -> 198 | M11: =M10+'Втрати ЗСУ'!$C11 -> 10057 | N11: =N10+'Втрати ЗСУ'!$D11 -> 11041 | O11: =O10+'Втрати ЗСУ'!$E11 -> 9054 | P11: =P10+'Втрати ЗСУ'!$F11 -> 8046 | Q11: =SUM('Втрати ЗСУ'!$M11:$P11) -> 38198
A12: 46032 | B12: ВСЬОГО за СО: | C12: =RANDBETWEEN(1,10) -> 7 | D12: =RANDBETWEEN(1,10) -> 9 | E12: =RANDBETWEEN(1,10) -> 10 | F12: =RANDBETWEEN(1,10) -> 5 | G12: =SUM('Втрати ЗСУ'!$C12:$F12) -> 31 | H12: =H11+'Втрати ЗСУ'!$C12 -> 64 | I12: =I11+'Втрати ЗСУ'!$D12 -> 50 | J12: =J11+'Втрати ЗСУ'!$E12 -> 64 | K12: =K11+'Втрати ЗСУ'!$F12 -> 51 | L12: =SUM('Втрати ЗСУ'!$H12:$K12) -> 229 | M12: =M11+'Втрати ЗСУ'!$C12 -> 10064 | N12: =N11+'Втрати ЗСУ'!$D12 -> 11050 | O12: =O11+'Втрати ЗСУ'!$E12 -> 9064 | P12: =P11+'Втрати ЗСУ'!$F12 -> 8051 | Q12: =SUM('Втрати ЗСУ'!$M12:$P12) -> 38229
A13: 46033 | B13: ВСЬОГО за СО: | C13: =RANDBETWEEN(1,10) -> 5 | D13: =RANDBETWEEN(1,10) -> 8 | E13: =RANDBETWEEN(1,10) -> 7 | F13: =RANDBETWEEN(1,10) -> 9 | G13: =SUM('Втрати ЗСУ'!$C13:$F13) -> 29 | H13: =H12+'Втрати ЗСУ'!$C13 -> 69 | I13: =I12+'Втрати ЗСУ'!$D13 -> 58 | J13: =J12+'Втрати ЗСУ'!$E13 -> 71 | K13: =K12+'Втрати ЗСУ'!$F13 -> 60 | L13: =SUM('Втрати ЗСУ'!$H13:$K13) -> 258 | M13: =M12+'Втрати ЗСУ'!$C13 -> 10069 | N13: =N12+'Втрати ЗСУ'!$D13 -> 11058 | O13: =O12+'Втрати ЗСУ'!$E13 -> 9071 | P13: =P12+'Втрати ЗСУ'!$F13 -> 8060 | Q13: =SUM('Втрати ЗСУ'!$M13:$P13) -> 38258
A14: 46034 | B14: ВСЬОГО за СО: | C14: =RANDBETWEEN(1,10) -> 9 | D14: =RANDBETWEEN(1,10) -> 7 | E14: =RANDBETWEEN(1,10) -> 5 | F14: =RANDBETWEEN(1,10) -> 3 | G14: =SUM('Втрати ЗСУ'!$C14:$F14) -> 24 | H14: =H13+'Втрати ЗСУ'!$C14 -> 78 | I14: =I13+'Втрати ЗСУ'!$D14 -> 65 | J14: =J13+'Втрати ЗСУ'!$E14 -> 76 | K14: =K13+'Втрати ЗСУ'!$F14 -> 63 | L14: =SUM('Втрати ЗСУ'!$H14:$K14) -> 282 | M14: =M13+'Втрати ЗСУ'!$C14 -> 10078 | N14: =N13+'Втрати ЗСУ'!$D14 -> 11065 | O14: =O13+'Втрати ЗСУ'!$E14 -> 9076 | P14: =P13+'Втрати ЗСУ'!$F14 -> 8063 | Q14: =SUM('Втрати ЗСУ'!$M14:$P14) -> 38282
... A94: 46295 | B94: ВСЬОГО за СО: | C94: =RANDBETWEEN(1,10) -> 10 | D94: =RANDBETWEEN(1,10) -> 6 | E94: =RANDBETWEEN(1,10) -> 7 | F94: =RANDBETWEEN(1,10) -> 4 | G94: =SUM('Втрати ЗСУ'!$C94:$F94) -> 27 | H94: =H93+'Втрати ЗСУ'!$C94 -> 568 | I94: =I93+'Втрати ЗСУ'!$D94 -> 545 | J94: =J93+'Втрати ЗСУ'!$E94 -> 498 | K94: =K93+'Втрати ЗСУ'!$F94 -> 506 | L94: =SUM('Втрати ЗСУ'!$H94:$K94) -> 2117 | M94: =M93+'Втрати ЗСУ'!$C94 -> 10568 | N94: =N93+'Втрати ЗСУ'!$D94 -> 11545 | O94: =O93+'Втрати ЗСУ'!$E94 -> 9498 | P94: =P93+'Втрати ЗСУ'!$F94 -> 8506 | Q94: =SUM('Втрати ЗСУ'!$M94:$P94) -> 40117

Sheet Застосування БК та FPV
A1: Дата | B1: Противник_БК | C1: Наші війська_БК | D1: Противник_FPV | E1: Наші війська_FPV
A2: 46204 | B2: =RANDBETWEEN(500,5000) -> 4083 | C2: =RANDBETWEEN(500,5000) -> 1570 | D2: =RANDBETWEEN(500,5000) -> 4210 | E2: =RANDBETWEEN(500,5000) -> 2128
A3: 46205 | B3: =RANDBETWEEN(500,5000) -> 3578 | C3: =RANDBETWEEN(500,5000) -> 4713 | D3: =RANDBETWEEN(500,5000) -> 2298 | E3: =RANDBETWEEN(500,5000) -> 790
A4: 46206 | B4: =RANDBETWEEN(500,5000) -> 2116 | C4: =RANDBETWEEN(500,5000) -> 2971 | D4: =RANDBETWEEN(500,5000) -> 1375 | E4: =RANDBETWEEN(500,5000) -> 578
A5: 46207 | B5: =RANDBETWEEN(500,5000) -> 2982 | C5: =RANDBETWEEN(500,5000) -> 4678 | D5: =RANDBETWEEN(500,5000) -> 4450 | E5: =RANDBETWEEN(500,5000) -> 2300
A6: 46208 | B6: =RANDBETWEEN(500,5000) -> 1344 | C6: =RANDBETWEEN(500,5000) -> 4014 | D6: =RANDBETWEEN(500,5000) -> 2817 | E6: =RANDBETWEEN(500,5000) -> 2777
A7: 46209 | B7: =RANDBETWEEN(500,5000) -> 2715 | C7: =RANDBETWEEN(500,5000) -> 1867 | D7: =RANDBETWEEN(500,5000) -> 4819 | E7: =RANDBETWEEN(500,5000) -> 2794
A8: 46210 | B8: =RANDBETWEEN(500,5000) -> 4885 | C8: =RANDBETWEEN(500,5000) -> 1419 | D8: =RANDBETWEEN(500,5000) -> 2106 | E8: =RANDBETWEEN(500,5000) -> 4413
A9: 46211 | B9: =RANDBETWEEN(500,5000) -> 3250 | C9: =RANDBETWEEN(500,5000) -> 3421 | D9: =RANDBETWEEN(500,5000) -> 3202 | E9: =RANDBETWEEN(500,5000) -> 4089
A10: 46212 | B10: =RANDBETWEEN(500,5000) -> 1706 | C10: =RANDBETWEEN(500,5000) -> 4493 | D10: =RANDBETWEEN(500,5000) -> 4216 | E10: =RANDBETWEEN(500,5000) -> 1555
A11: 46213 | B11: =RANDBETWEEN(500,5000) -> 3178 | C11: =RANDBETWEEN(500,5000) -> 2019 | D11: =RANDBETWEEN(500,5000) -> 3521 | E11: =RANDBETWEEN(500,5000) -> 1875
A12: 46214 | B12: =RANDBETWEEN(500,5000) -> 3289 | C12: =RANDBETWEEN(500,5000) -> 1130 | D12: =RANDBETWEEN(500,5000) -> 2388 | E12: =RANDBETWEEN(500,5000) -> 4725
A13: 46215 | B13: =RANDBETWEEN(500,5000) -> 3347 | C13: =RANDBETWEEN(500,5000) -> 2766 | D13: =RANDBETWEEN(500,5000) -> 567 | E13: =RANDBETWEEN(500,5000) -> 3641
... A231: 46433 | B231: =RANDBETWEEN(500,5000) -> 1154 | C231: =RANDBETWEEN(500,5000) -> 3180 | D231: =RANDBETWEEN(500,5000) -> 2055 | E231: =RANDBETWEEN(500,5000) -> 3704

Sheet ОВгП
A1: Дата | B1: засоби | C1: тип | D1: категорія | E1: УСБпС | G1: УВ (с) "Захід" | I1: 12 АК | K1: 15 АК | M1: 18 АК | O1: УВ (с) "Північ" | Q1: УВ "Курськ" | S1: 14 АК | U1: 2 КНГУ "Хартія" | W1: 16 АК | Y1: 10 АК | AA1: 3 АК | AC1: УОС | AE1: 11 АК | AG1: 19 АК | AI1: 1 КНГУ "Азов" | AK1: 7 КШР | AM1: Покровський н. | AO1: 9 АК | AQ1: УВ (с) "Схід" | AS1: 20 АК | AU1: Олександрівський н. | AW1: 17 АК | AY1: 30 КМП | BA1: ОТУ "Одеса" | BC1: УВ (с) "Південь" | BE1: ВСЬОГО за СО | BG1: вартість | BH1: артість_за_шт
E2: вз | F2: бп | G2: вз | H2: бп | I2: вз | J2: бп | K2: вз | L2: бп | M2: вз | N2: бп | O2: вз | P2: бп | Q2: вз | R2: бп | S2: вз | T2: бп | U2: вз | V2: бп | W2: вз | X2: бп | Y2: вз | Z2: бп | AA2: вз | AB2: бп | AC2: вз | AD2: бп | AE2: вз | AF2: бп | AG2: вз | AH2: бп | AI2: вз | AJ2: бп | AK2: вз | AL2: бп | AM2: вз | AN2: бп | AO2: вз | AP2: бп | AQ2: вз | AR2: бп | AS2: вз | AT2: бп | AU2: вз | AV2: бп | AW2: вз | AX2: бп | AY2: вз | AZ2: бп | BA2: вз | BB2: бп | BC2: вз | BD2: бп | BE2: вз | BF2: бп
A4: 46261 | B4: 227 мм М26 | C4: РСЗВ | D4: важкий | E4: =ROUNDUP(F4/3,0) -> 2 | F4: =RANDBETWEEN(0,4) -> 4 | G4: =ROUNDUP(H4/3,0) -> 1 | H4: =RANDBETWEEN(0,4) -> 3 | I4: =ROUNDUP(J4/3,0) -> 1 | J4: =RANDBETWEEN(0,4) -> 2 | K4: =ROUNDUP(L4/3,0) -> 1 | L4: =RANDBETWEEN(0,4) -> 1 | M4: =ROUNDUP(N4/3,0) -> 1 | N4: =RANDBETWEEN(0,4) -> 2 | O4: =SUM(K4,M4) -> 2 | P4: =SUM(L4,N4) -> 3 | Q4: =ROUNDUP(R4/3,0) -> 1 | R4: =RANDBETWEEN(0,4) -> 3 | S4: =ROUNDUP(T4/3,0) -> 1 | T4: =RANDBETWEEN(0,4) -> 3 | U4: =ROUNDUP(V4/3,0) -> 2 | V4: =RANDBETWEEN(0,4) -> 4 | W4: =ROUNDUP(X4/3,0) -> 0 | X4: =RANDBETWEEN(0,4) -> 0 | Y4: =ROUNDUP(Z4/3,0) -> 0 | Z4: =RANDBETWEEN(0,4) -> 0 | AA4: =ROUNDUP(AB4/3,0) -> 1 | AB4: =RANDBETWEEN(0,4) -> 2 | AC4: =SUM(S4,U4,W4,Y4,AA4) -> 4 | AD4: =SUM(T4,V4,X4,Z4,AB4) -> 9 | AE4: =ROUNDUP(AF4/3,0) -> 2 | AF4: =RANDBETWEEN(0,4) -> 4 | AG4: =ROUNDUP(AH4/3,0) -> 1 | AH4: =RANDBETWEEN(0,4) -> 1 | AI4: =ROUNDUP(AJ4/3,0) -> 1 | AJ4: =RANDBETWEEN(0,4) -> 3 | AK4: =ROUNDUP(AL4/3,0) -> 2 | AL4: =RANDBETWEEN(0,4) -> 4 | AM4: =ROUNDUP(AN4/3,0) -> 2 | AN4: =RANDBETWEEN(0,4) -> 4 | AO4: =ROUNDUP(AP4/3,0) -> 1 | AP4: =RANDBETWEEN(0,4) -> 1 | AQ4: =SUM(AG4,AI4,AK4,AM4,AO4) -> 7 | AR4: =SUM(AH4,AJ4,AL4,AN4,AP4) -> 13 | AS4: =ROUNDUP(AT4/3,0) -> 2 | AT4: =RANDBETWEEN(0,4) -> 4 | AU4: =ROUNDUP(AV4/3,0) -> 0 | AV4: =RANDBETWEEN(0,4) -> 0 | AW4: =ROUNDUP(AX4/3,0) -> 1 | AX4: =RANDBETWEEN(0,4) -> 2 | AY4: =ROUNDUP(AZ4/3,0) -> 1 | AZ4: =RANDBETWEEN(0,4) -> 2 | BA4: =ROUNDUP(BB4/3,0) -> 2 | BB4: =RANDBETWEEN(0,4) -> 4 | BC4: =SUM(AS4,AU4,AW4,AY4,BA4) -> 6 | BD4: =SUM(AT4,AV4,AX4,AZ4,BB4) -> 12 | BE4: =SUM(E4,G4,I4,O4,Q4,AC4,AQ4,BC4) -> 24 | BF4: =SUM(F4,H4,J4,P4,R4,AD4,AR4,BD4) -> 49 | BG4: =BF4*'ОВгП_РАО'!$B$2 -> #REF! | BH4: ='ОВгП_РАО'!$B$2 -> #REF!
A5: =A4 -> 46261 | B5: 227 мм М30 | C5: РСЗВ | D5: важкий | E5: =ROUNDUP(F5/3,0) -> 1 | F5: =RANDBETWEEN(0,4) -> 3 | G5: =ROUNDUP(H5/3,0) -> 1 | H5: =RANDBETWEEN(0,4) -> 2 | I5: =ROUNDUP(J5/3,0) -> 0 | J5: =RANDBETWEEN(0,4) -> 0 | K5: =ROUNDUP(L5/3,0) -> 1 | L5: =RANDBETWEEN(0,4) -> 2 | M5: =ROUNDUP(N5/3,0) -> 2 | N5: =RANDBETWEEN(0,4) -> 4 | O5: =SUM(K5,M5) -> 3 | P5: =SUM(L5,N5) -> 6 | Q5: =ROUNDUP(R5/3,0) -> 1 | R5: =RANDBETWEEN(0,4) -> 3 | S5: =ROUNDUP(T5/3,0) -> 1 | T5: =RANDBETWEEN(0,4) -> 1 | U5: =ROUNDUP(V5/3,0) -> 1 | V5: =RANDBETWEEN(0,4) -> 3 | W5: =ROUNDUP(X5/3,0) -> 1 | X5: =RANDBETWEEN(0,4) -> 2 | Y5: =ROUNDUP(Z5/3,0) -> 2 | Z5: =RANDBETWEEN(0,4) -> 4 | AA5: =ROUNDUP(AB5/3,0) -> 1 | AB5: =RANDBETWEEN(0,4) -> 1 | AC5: =SUM(S5,U5,W5,Y5,AA5) -> 6 | AD5: =SUM(T5,V5,X5,Z5,AB5) -> 11 | AE5: =ROUNDUP(AF5/3,0) -> 1 | AF5: =RANDBETWEEN(0,4) -> 3 | AG5: =ROUNDUP(AH5/3,0) -> 2 | AH5: =RANDBETWEEN(0,4) -> 4 | AI5: =ROUNDUP(AJ5/3,0) -> 1 | AJ5: =RANDBETWEEN(0,4) -> 1 | AK5: =ROUNDUP(AL5/3,0) -> 1 | AL5: =RANDBETWEEN(0,4) -> 1 | AM5: =ROUNDUP(AN5/3,0) -> 1 | AN5: =RANDBETWEEN(0,4) -> 3 | AO5: =ROUNDUP(AP5/3,0) -> 2 | AP5: =RANDBETWEEN(0,4) -> 4 | AQ5: =SUM(AG5,AI5,AK5,AM5,AO5) -> 7 | AR5: =SUM(AH5,AJ5,AL5,AN5,AP5) -> 13 | AS5: =ROUNDUP(AT5/3,0) -> 0 | AT5: =RANDBETWEEN(0,4) -> 0 | AU5: =ROUNDUP(AV5/3,0) -> 2 | AV5: =RANDBETWEEN(0,4) -> 4 | AW5: =ROUNDUP(AX5/3,0) -> 1 | AX5: =RANDBETWEEN(0,4) -> 3 | AY5: =ROUNDUP(AZ5/3,0) -> 1 | AZ5: =RANDBETWEEN(0,4) -> 1 | BA5: =ROUNDUP(BB5/3,0) -> 1 | BB5: =RANDBETWEEN(0,4) -> 3 | BC5: =SUM(AS5,AU5,AW5,AY5,BA5) -> 5 | BD5: =SUM(AT5,AV5,AX5,AZ5,BB5) -> 11 | BE5: =SUM(E5,G5,I5,O5,Q5,AC5,AQ5,BC5) -> 24 | BF5: =SUM(F5,H5,J5,P5,R5,AD5,AR5,BD5) -> 49 | BG5: =BF5*'ОВгП_РАО'!$B$3 -> #REF! | BH5: ='ОВгП_РАО'!$B$3 -> #REF!
